Workbook

Sheet 맵 보상 기준
B1: 등급 | C1: 기준 보상액 | D1: 실버 추가 보상 | E1: 골드 추가 보상 | F1: 기본 보상액 | G1: 랜덤 보상액
B2: 1 | C2: =설정!$B$1*설정!$B$2*(1+설정!$B$3*'맵 보상 기준'!$B2) -> 720 | D2: =$C2*설정!$B$4 -> 360 | E2: =$C2*설정!$B$4*2 -> 720 | F2: =$C2*(1-설정!$B$5) -> 576 | G2: =$C2*설정!$B$5 -> 144
B3: 2 | C3: =설정!$B$1*설정!$B$2*(1+설정!$B$3*'맵 보상 기준'!$B3) -> 840 | D3: =$C3*설정!$B$4 -> 420 | E3: =$C3*설정!$B$4*2 -> 840 | F3: =$C3*(1-설정!$B$5) -> 672 | G3: =$C3*설정!$B$5 -> 168
B4: 3 | C4: =설정!$B$1*설정!$B$2*(1+설정!$B$3*'맵 보상 기준'!$B4) -> 960 | D4: =$C4*설정!$B$4 -> 480 | E4: =$C4*설정!$B$4*2 -> 960 | F4: =$C4*(1-설정!$B$5) -> 768 | G4: =$C4*설정!$B$5 -> 192
B5: 4 | C5: =설정!$B$1*설정!$B$2*(1+설정!$B$3*'맵 보상 기준'!$B5) -> 1080 | D5: =$C5*설정!$B$4 -> 540 | E5: =$C5*설정!$B$4*2 -> 1080 | F5: =$C5*(1-설정!$B$5) -> 864 | G5: =$C5*설정!$B$5 -> 216
A10: 이름 | B10: 등급 | C10: 결과 | D10: 기준 보상액 | E10: 실 보상액 | F10: Gold | G10: Add_Gold | H10: Coin | I10: Add_Coin | J10: Item_1 | K10: Prob_1 | L10: Item_2 | M10: Prob_2 | N10: Item_3 | O10: Prob_3 | P10: Item_4 | Q10: Prob_4 | R10: Item_5 | S10: Prob_5 | T10: Item_6 | U10: Prob_6 | V10: Item_7 | W10: Prob_7 | X10: Item_8 | Y10: Prob_8 | Z10: Item_9 | AA10: Prob_9 | AB10: Item_10 | AC10: Prob_10 | AD10: Price1 | AE10: Price2 | AF10: Price3 | AG10: Price4 | AH10: Price5 | AI10: Price6 | AJ10: Price7 | AK10: Price8 | AL10: Price9 | AM10: Price10
A11: D등급 맵 보상 | B11: 1 | C11: 0 | D11: =VLOOKUP(B11,$B$2:$G$5,2+C11,FALSE) -> 720 | E11: =F11+G11*0.5+SUM(AD11:AM11) -> 720 | F11: =IF(C11>0,0,VLOOKUP(B11,$B$2:$G$5,5,FALSE)) -> 576 | G11: =IF(C11>0,0,VLOOKUP(B11,$B$2:$G$5,6,FALSE))*2 -> 288 | AD11: =IF(J11="",0,VLOOKUP(J11,Table_Data_Item!$C:$W,21,FALSE)*K11/10000) -> 0 | AE11: =IF(L11="",0,VLOOKUP(L11,Table_Data_Item!$C:$W,21,FALSE)*M11/10000) -> 0 | AF11: =IF(N11="",0,VLOOKUP(N11,Table_Data_Item!$C:$W,21,FALSE)*O11/10000) -> 0 | AG11: =IF(P11="",0,VLOOKUP(P11,Table_Data_Item!$C:$W,21,FALSE)*Q11/10000) -> 0 | AH11: =IF(R11="",0,VLOOKUP(R11,Table_Data_Item!$C:$W,21,FALSE)*S11/10000) -> 0 | AI11: =IF(T11="",0,VLOOKUP(T11,Table_Data_Item!$C:$W,21,FALSE)*U11/10000) -> 0 | AJ11: =IF(V11="",0,VLOOKUP(V11,Table_Data_Item!$C:$W,21,FALSE)*W11/10000) -> 0 | AK11: =IF(X11="",0,VLOOKUP(X11,Table_Data_Item!$C:$W,21,FALSE)*Y11/10000) -> 0 | AL11: =IF(Z11="",0,VLOOKUP(Z11,Table_Data_Item!$C:$W,21,FALSE)*AA11/10000) -> 0 | AM11: =IF(AB11="",0,VLOOKUP(AB11,Table_Data_Item!$C:$W,21,FALSE)*AC11/10000) -> 0
A12: D등급 맵 실버 보상 | B12: 1 | C12: 1 | D12: =VLOOKUP(B12,$B$2:$G$5,2+C12,FALSE) -> 360 | E12: =F12+G12*0.5+SUM(AD12:AM12) -> 320 | F12: =IF(C12>0,0,VLOOKUP(B12,$B$2:$G$5,5,FALSE)) -> 0 | G12: =IF(C12>0,0,VLOOKUP(B12,$B$2:$G$5,6,FALSE))*2 -> 0 | J12: item_potion_heal_01 | K12: 6000 | L12: item_equip_n_ar_02 | M12: 100 | N12: item_equip_n_ar_05 | O12: 100 | P12: item_equip_n_ac_02 | Q12: 100 | R12: item_equip_n_bo_02 | S12: 100 | AD12: =IF(J12="",0,VLOOKUP(J12,Table_Data_Item!$C:$W,21,FALSE)*K12/10000) -> 120 | AE12: =IF(L12="",0,VLOOKUP(L12,Table_Data_Item!$C:$W,21,FALSE)*M12/10000) -> 50 | AF12: =IF(N12="",0,VLOOKUP(N12,Table_Data_Item!$C:$W,21,FALSE)*O12/10000) -> 50 | AG12: =IF(P12="",0,VLOOKUP(P12,Table_Data_Item!$C:$W,21,FALSE)*Q12/10000) -> 62.5 | AH12: =IF(R12="",0,VLOOKUP(R12,Table_Data_Item!$C:$W,21,FALSE)*S12/10000) -> 37.5 | AI12: =IF(T12="",0,VLOOKUP(T12,Table_Data_Item!$C:$W,21,FALSE)*U12/10000) -> 0 | AJ12: =IF(V12="",0,VLOOKUP(V12,Table_Data_Item!$C:$W,21,FALSE)*W12/10000) -> 0 | AK12: =IF(X12="",0,VLOOKUP(X12,Table_Data_Item!$C:$W,21,FALSE)*Y12/10000) -> 0 | AL12: =IF(Z12="",0,VLOOKUP(Z12,Table_Data_Item!$C:$W,21,FALSE)*AA12/10000) -> 0 | AM12: =IF(AB12="",0,VLOOKUP(AB12,Table_Data_Item!$C:$W,21,FALSE)*AC12/10000) -> 0
A13: D등급 맵 골드 보상 | B13: 1 | C13: 2 | D13: =VLOOKUP(B13,$B$2:$G$5,2+C13,FALSE) -> 720 | E13: =F13+G13*0.5+SUM(AD13:AM13) -> 675 | F13: =IF(C13>0,0,VLOOKUP(B13,$B$2:$G$5,5,FALSE)) -> 0 | G13: =IF(C13>0,0,VLOOKUP(B13,$B$2:$G$5,6,FALSE))*2 -> 0 | J13: item_equip_n_we_02 | K13: 300 | L13: item_equip_n_we_05 | M13: 300 | N13: item_equip_n_we_08 | O13: 300 | AD13: =IF(J13="",0,VLOOKUP(J13,Table_Data_Item!$C:$W,21,FALSE)*K13/10000) -> 225 | AE13: =IF(L13="",0,VLOOKUP(L13,Table_Data_Item!$C:$W,21,FALSE)*M13/10000) -> 225 | AF13: =IF(N13="",0,VLOOKUP(N13,Table_Data_Item!$C:$W,21,FALSE)*O13/10000) -> 225 | AG13: =IF(P13="",0,VLOOKUP(P13,Table_Data_Item!$C:$W,21,FALSE)*Q13/10000) -> 0 | AH13: =IF(R13="",0,VLOOKUP(R13,Table_Data_Item!$C:$W,21,FALSE)*S13/10000) -> 0 | AI13: =IF(T13="",0,VLOOKUP(T13,Table_Data_Item!$C:$W,21,FALSE)*U13/10000) -> 0 | AJ13: =IF(V13="",0,VLOOKUP(V13,Table_Data_Item!$C:$W,21,FALSE)*W13/10000) -> 0 | AK13: =IF(X13="",0,VLOOKUP(X13,Table_Data_Item!$C:$W,21,FALSE)*Y13/10000) -> 0 | AL13: =IF(Z13="",0,VLOOKUP(Z13,Table_Data_Item!$C:$W,21,FALSE)*AA13/10000) -> 0 | AM13: =IF(AB13="",0,VLOOKUP(AB13,Table_Data_Item!$C:$W,21,FALSE)*AC13/10000) -> 0
A14: C등급 맵 보상 | B14: 2 | C14: 0 | D14: =VLOOKUP(B14,$B$2:$G$5,2+C14,FALSE) -> 840 | E14: =F14+G14*0.5+SUM(AD14:AM14) -> 840 | F14: =IF(C14>0,0,VLOOKUP(B14,$B$2:$G$5,5,FALSE)) -> 672 | G14: =IF(C14>0,0,VLOOKUP(B14,$B$2:$G$5,6,FALSE))*2 -> 336 | AD14: =IF(J14="",0,VLOOKUP(J14,Table_Data_Item!$C:$W,21,FALSE)*K14/10000) -> 0 | AE14: =IF(L14="",0,VLOOKUP(L14,Table_Data_Item!$C:$W,21,FALSE)*M14/10000) -> 0 | AF14: =IF(N14="",0,VLOOKUP(N14,Table_Data_Item!$C:$W,21,FALSE)*O14/10000) -> 0 | AG14: =IF(P14="",0,VLOOKUP(P14,Table_Data_Item!$C:$W,21,FALSE)*Q14/10000) -> 0 | AH14: =IF(R14="",0,VLOOKUP(R14,Table_Data_Item!$C:$W,21,FALSE)*S14/10000) -> 0 | AI14: =IF(T14="",0,VLOOKUP(T14,Table_Data_Item!$C:$W,21,FALSE)*U14/10000) -> 0 | AJ14: =IF(V14="",0,VLOOKUP(V14,Table_Data_Item!$C:$W,21,FALSE)*W14/10000) -> 0 | AK14: =IF(X14="",0,VLOOKUP(X14,Table_Data_Item!$C:$W,21,FALSE)*Y14/10000) -> 0 | AL14: =IF(Z14="",0,VLOOKUP(Z14,Table_Data_Item!$C:$W,21,FALSE)*AA14/10000) -> 0 | AM14: =IF(AB14="",0,VLOOKUP(AB14,Table_Data_Item!$C:$W,21,FALSE)*AC14/10000) -> 0
A15: C등급 맵 실버 보상 | B15: 2 | C15: 1 | D15: =VLOOKUP(B15,$B$2:$G$5,2+C15,FALSE) -> 420 | E15: =F15+G15*0.5+SUM(AD15:AM15) -> 1180 | F15: =IF(C15>0,0,VLOOKUP(B15,$B$2:$G$5,5,FALSE)) -> 0 | G15: =IF(C15>0,0,VLOOKUP(B15,$B$2:$G$5,6,FALSE))*2 -> 0 | J15: item_potion_heal_02 | K15: 3000 | L15: item_equip_n_ac_05 | M15: 100 | N15: item_equip_n_bo_05 | O15: 100 | P15: item_equip_n_ar_08 | Q15: 100 | R15: item_equip_n_ar_11 | S15: 100 | AD15: =IF(J15="",0,VLOOKUP(J15,Table_Data_Item!$C:$W,21,FALSE)*K15/10000) -> 180 | AE15: =IF(L15="",0,VLOOKUP(L15,Table_Data_Item!$C:$W,21,FALSE)*M15/10000) -> 312.5 | AF15: =IF(N15="",0,VLOOKUP(N15,Table_Data_Item!$C:$W,21,FALSE)*O15/10000) -> 187.5 | AG15: =IF(P15="",0,VLOOKUP(P15,Table_Data_Item!$C:$W,21,FALSE)*Q15/10000) -> 250 | AH15: =IF(R15="",0,VLOOKUP(R15,Table_Data_Item!$C:$W,21,FALSE)*S15/10000) -> 250 | AI15: =IF(T15="",0,VLOOKUP(T15,Table_Data_Item!$C:$W,21,FALSE)*U15/10000) -> 0 | AJ15: =IF(V15="",0,VLOOKUP(V15,Table_Data_Item!$C:$W,21,FALSE)*W15/10000) -> 0 | AK15: =IF(X15="",0,VLOOKUP(X15,Table_Data_Item!$C:$W,21,FALSE)*Y15/10000) -> 0 | AL15: =IF(Z15="",0,VLOOKUP(Z15,Table_Data_Item!$C:$W,21,FALSE)*AA15/10000) -> 0 | AM15: =IF(AB15="",0,VLOOKUP(AB15,Table_Data_Item!$C:$W,21,FALSE)*AC15/10000) -> 0
A16: C등급 맵 골드 보상 | B16: 2 | C16: 2 | D16: =VLOOKUP(B16,$B$2:$G$5,2+C16,FALSE) -> 840 | E16: =F16+G16*0.5+SUM(AD16:AM16) -> 2250 | F16: =IF(C16>0,0,VLOOKUP(B16,$B$2:$G$5,5,FALSE)) -> 0 | G16: =IF(C16>0,0,VLOOKUP(B16,$B$2:$G$5,6,FALSE))*2 -> 0 | J16: item_equip_n_we_11 | K16: 200 | L16: item_equip_n_we_14 | M16: 200 | N16: item_equip_n_we_17 | O16: 200 | AD16: =IF(J16="",0,VLOOKUP(J16,Table_Data_Item!$C:$W,21,FALSE)*K16/10000) -> 750 | AE16: =IF(L16="",0,VLOOKUP(L16,Table_Data_Item!$C:$W,21,FALSE)*M16/10000) -> 750 | AF16: =IF(N16="",0,VLOOKUP(N16,Table_Data_Item!$C:$W,21,FALSE)*O16/10000) -> 750 | AG16: =IF(P16="",0,VLOOKUP(P16,Table_Data_Item!$C:$W,21,FALSE)*Q16/10000) -> 0 | AH16: =IF(R16="",0,VLOOKUP(R16,Table_Data_Item!$C:$W,21,FALSE)*S16/10000) -> 0 | AI16: =IF(T16="",0,VLOOKUP(T16,Table_Data_Item!$C:$W,21,FALSE)*U16/10000) -> 0 | AJ16: =IF(V16="",0,VLOOKUP(V16,Table_Data_Item!$C:$W,21,FALSE)*W16/10000) -> 0 | AK16: =IF(X16="",0,VLOOKUP(X16,Table_Data_Item!$C:$W,21,FALSE)*Y16/10000) -> 0 | AL16: =IF(Z16="",0,VLOOKUP(Z16,Table_Data_Item!$C:$W,21,FALSE)*AA16/10000) -> 0 | AM16: =IF(AB16="",0,VLOOKUP(AB16,Table_Data_Item!$C:$W,21,FALSE)*AC16/10000) -> 0
A17: B등급 맵 보상 | B17: 3 | C17: 0 | D17: =VLOOKUP(B17,$B$2:$G$5,2+C17,FALSE) -> 960 | E17: =F17+G17*0.5+SUM(AD17:AM17) -> 960 | F17: =IF(C17>0,0,VLOOKUP(B17,$B$2:$G$5,5,FALSE)) -> 768 | G17: =IF(C17>0,0,VLOOKUP(B17,$B$2:$G$5,6,FALSE))*2 -> 384 | AD17: =IF(J17="",0,VLOOKUP(J17,Table_Data_Item!$C:$W,21,FALSE)*K17/10000) -> 0 | AE17: =IF(L17="",0,VLOOKUP(L17,Table_Data_Item!$C:$W,21,FALSE)*M17/10000) -> 0 | AF17: =IF(N17="",0,VLOOKUP(N17,Table_Data_Item!$C:$W,21,FALSE)*O17/10000) -> 0 | AG17: =IF(P17="",0,VLOOKUP(P17,Table_Data_Item!$C:$W,21,FALSE)*Q17/10000) -> 0 | AH17: =IF(R17="",0,VLOOKUP(R17,Table_Data_Item!$C:$W,21,FALSE)*S17/10000) -> 0 | AI17: =IF(T17="",0,VLOOKUP(T17,Table_Data_Item!$C:$W,21,FALSE)*U17/10000) -> 0 | AJ17: =IF(V17="",0,VLOOKUP(V17,Table_Data_Item!$C:$W,21,FALSE)*W17/10000) -> 0 | AK17: =IF(X17="",0,VLOOKUP(X17,Table_Data_Item!$C:$W,21,FALSE)*Y17/10000) -> 0 | AL17: =IF(Z17="",0,VLOOKUP(Z17,Table_Data_Item!$C:$W,21,FALSE)*AA17/10000) -> 0 | AM17: =IF(AB17="",0,VLOOKUP(AB17,Table_Data_Item!$C:$W,21,FALSE)*AC17/10000) -> 0
A18: B등급 맵 실버 보상 | B18: 3 | C18: 1 | D18: =VLOOKUP(B18,$B$2:$G$5,2+C18,FALSE) -> 480 | E18: =F18+G18*0.5+SUM(AD18:AM18) -> 2800 | F18: =IF(C18>0,0,VLOOKUP(B18,$B$2:$G$5,5,FALSE)) -> 0 | G18: =IF(C18>0,0,VLOOKUP(B18,$B$2:$G$5,6,FALSE))*2 -> 0 | J18: item_potion_heal_03 | K18: 3000 | L18: item_equip_n_ar_14 | M18: 50 | N18: item_equip_n_ar_17 | O18: 50 | P18: item_equip_n_ac_08 | Q18: 50 | R18: item_equip_n_bo_08 | S18: 50 | AD18: =IF(J18="",0,VLOOKUP(J18,Table_Data_Item!$C:$W,21,FALSE)*K18/10000) -> 300 | AE18: =IF(L18="",0,VLOOKUP(L18,Table_Data_Item!$C:$W,21,FALSE)*M18/10000) -> 625 | AF18: =IF(N18="",0,VLOOKUP(N18,Table_Data_Item!$C:$W,21,FALSE)*O18/10000) -> 625 | AG18: =IF(P18="",0,VLOOKUP(P18,Table_Data_Item!$C:$W,21,FALSE)*Q18/10000) -> 781.25 | AH18: =IF(R18="",0,VLOOKUP(R18,Table_Data_Item!$C:$W,21,FALSE)*S18/10000) -> 468.75 | AI18: =IF(T18="",0,VLOOKUP(T18,Table_Data_Item!$C:$W,21,FALSE)*U18/10000) -> 0 | AJ18: =IF(V18="",0,VLOOKUP(V18,Table_Data_Item!$C:$W,21,FALSE)*W18/10000) -> 0 | AK18: =IF(X18="",0,VLOOKUP(X18,Table_Data_Item!$C:$W,21,FALSE)*Y18/10000) -> 0 | AL18: =IF(Z18="",0,VLOOKUP(Z18,Table_Data_Item!$C:$W,21,FALSE)*AA18/10000) -> 0 | AM18: =IF(AB18="",0,VLOOKUP(AB18,Table_Data_Item!$C:$W,21,FALSE)*AC18/10000) -> 0
A19: B등급 맵 골드 보상 | B19: 3 | C19: 2 | D19: =VLOOKUP(B19,$B$2:$G$5,2+C19,FALSE) -> 960 | E19: =F19+G19*0.5+SUM(AD19:AM19) -> 5625 | F19: =IF(C19>0,0,VLOOKUP(B19,$B$2:$G$5,5,FALSE)) -> 0 | G19: =IF(C19>0,0,VLOOKUP(B19,$B$2:$G$5,6,FALSE))*2 -> 0 | J19: item_equip_n_we_20 | K19: 100 | L19: item_equip_n_we_23 | M19: 100 | N19: item_equip_n_we_26 | O19: 100 | AD19: =IF(J19="",0,VLOOKUP(J19,Table_Data_Item!$C:$W,21,FALSE)*K19/10000) -> 1875 | AE19: =IF(L19="",0,VLOOKUP(L19,Table_Data_Item!$C:$W,21,FALSE)*M19/10000) -> 1875 | AF19: =IF(N19="",0,VLOOKUP(N19,Table_Data_Item!$C:$W,21,FALSE)*O19/10000) -> 1875 | AG19: =IF(P19="",0,VLOOKUP(P19,Table_Data_Item!$C:$W,21,FALSE)*Q19/10000) -> 0 | AH19: =IF(R19="",0,VLOOKUP(R19,Table_Data_Item!$C:$W,21,FALSE)*S19/10000) -> 0 | AI19: =IF(T19="",0,VLOOKUP(T19,Table_Data_Item!$C:$W,21,FALSE)*U19/10000) -> 0 | AJ19: =IF(V19="",0,VLOOKUP(V19,Table_Data_Item!$C:$W,21,FALSE)*W19/10000) -> 0 | AK19: =IF(X19="",0,VLOOKUP(X19,Table_Data_Item!$C:$W,21,FALSE)*Y19/10000) -> 0 | AL19: =IF(Z19="",0,VLOOKUP(Z19,Table_Data_Item!$C:$W,21,FALSE)*AA19/10000) -> 0 | AM19: =IF(AB19="",0,VLOOKUP(AB19,Table_Data_Item!$C:$W,21,FALSE)*AC19/10000) -> 0
A20: A등급 맵 보상 | B20: 4 | C20: 0 | D20: =VLOOKUP(B20,$B$2:$G$5,2+C20,FALSE) -> 1080 | E20: =F20+G20*0.5+SUM(AD20:AM20) -> 1080 | F20: =IF(C20>0,0,VLOOKUP(B20,$B$2:$G$5,5,FALSE)) -> 864 | G20: =IF(C20>0,0,VLOOKUP(B20,$B$2:$G$5,6,FALSE))*2 -> 432 | AD20: =IF(J20="",0,VLOOKUP(J20,Table_Data_Item!$C:$W,21,FALSE)*K20/10000) -> 0 | AE20: =IF(L20="",0,VLOOKUP(L20,Table_Data_Item!$C:$W,21,FALSE)*M20/10000) -> 0 | AF20: =IF(N20="",0,VLOOKUP(N20,Table_Data_Item!$C:$W,21,FALSE)*O20/10000) -> 0 | AG20: =IF(P20="",0,VLOOKUP(P20,Table_Data_Item!$C:$W,21,FALSE)*Q20/10000) -> 0 | AH20: =IF(R20="",0,VLOOKUP(R20,Table_Data_Item!$C:$W,21,FALSE)*S20/10000) -> 0 | AI20: =IF(T20="",0,VLOOKUP(T20,Table_Data_Item!$C:$W,21,FALSE)*U20/10000) -> 0 | AJ20: =IF(V20="",0,VLOOKUP(V20,Table_Data_Item!$C:$W,21,FALSE)*W20/10000) -> 0 | AK20: =IF(X20="",0,VLOOKUP(X20,Table_Data_Item!$C:$W,21,FALSE)*Y20/10000) -> 0 | AL20: =IF(Z20="",0,VLOOKUP(Z20,Table_Data_Item!$C:$W,21,FALSE)*AA20/10000) -> 0 | AM20: =IF(AB20="",0,VLOOKUP(AB20,Table_Data_Item!$C:$W,21,FALSE)*AC20/10000) -> 0
A21: A등급 맵 실버 보상 | B21: 4 | C21: 1 | D21: =VLOOKUP(B21,$B$2:$G$5,2+C21,FALSE) -> 540 | E21: =F21+G21*0.5+SUM(AD21:AM21) -> 12875 | F21: =IF(C21>0,0,VLOOKUP(B21,$B$2:$G$5,5,FALSE)) -> 0 | G21: =IF(C21>0,0,VLOOKUP(B21,$B$2:$G$5,6,FALSE))*2 -> 0 | J21: item_potion_heal_04 | K21: 2500 | L21: item_equip_n_ar_20 | M21: 50 | N21: item_equip_n_ar_23 | O21: 50 | P21: item_equip_n_ac_11 | Q21: 50 | R21: item_equip_n_bo_11 | S21: 50 | AD21: =IF(J21="",0,VLOOKUP(J21,Table_Data_Item!$C:$W,21,FALSE)*K21/10000) -> 375 | AE21: =IF(L21="",0,VLOOKUP(L21,Table_Data_Item!$C:$W,21,FALSE)*M21/10000) -> 3125 | AF21: =IF(N21="",0,VLOOKUP(N21,Table_Data_Item!$C:$W,21,FALSE)*O21/10000) -> 3125 | AG21: =IF(P21="",0,VLOOKUP(P21,Table_Data_Item!$C:$W,21,FALSE)*Q21/10000) -> 3906.25 | AH21: =IF(R21="",0,VLOOKUP(R21,Table_Data_Item!$C:$W,21,FALSE)*S21/10000) -> 2343.75 | AI21: =IF(T21="",0,VLOOKUP(T21,Table_Data_Item!$C:$W,21,FALSE)*U21/10000) -> 0 | AJ21: =IF(V21="",0,VLOOKUP(V21,Table_Data_Item!$C:$W,21,FALSE)*W21/10000) -> 0 | AK21: =IF(X21="",0,VLOOKUP(X21,Table_Data_Item!$C:$W,21,FALSE)*Y21/10000) -> 0 | AL21: =IF(Z21="",0,VLOOKUP(Z21,Table_Data_Item!$C:$W,21,FALSE)*AA21/10000) -> 0 | AM21: =IF(AB21="",0,VLOOKUP(AB21,Table_Data_Item!$C:$W,21,FALSE)*AC21/10000) -> 0
A22: A등급 맵 골드 보상 | B22: 4 | C22: 2 | D22: =VLOOKUP(B22,$B$2:$G$5,2+C22,FALSE) -> 1080 | E22: =F22+G22*0.5+SUM(AD22:AM22) -> 14062.5 | F22: =IF(C22>0,0,VLOOKUP(B22,$B$2:$G$5,5,FALSE)) -> 0 | G22: =IF(C22>0,0,VLOOKUP(B22,$B$2:$G$5,6,FALSE))*2 -> 0 | J22: item_equip_n_we_29 | K22: 50 | L22: item_equip_n_we_32 | M22: 50 | N22: item_equip_n_we_35 | O22: 50 | AD22: =IF(J22="",0,VLOOKUP(J22,Table_Data_Item!$C:$W,21,FALSE)*K22/10000) -> 4687.5 | AE22: =IF(L22="",0,VLOOKUP(L22,Table_Data_Item!$C:$W,21,FALSE)*M22/10000) -> 4687.5 | AF22: =IF(N22="",0,VLOOKUP(N22,Table_Data_Item!$C:$W,21,FALSE)*O22/10000) -> 4687.5 | AG22: =IF(P22="",0,VLOOKUP(P22,Table_Data_Item!$C:$W,21,FALSE)*Q22/10000) -> 0 | AH22: =IF(R22="",0,VLOOKUP(R22,Table_Data_Item!$C:$W,21,FALSE)*S22/10000) -> 0 | AI22: =IF(T22="",0,VLOOKUP(T22,Table_Data_Item!$C:$W,21,FALSE)*U22/10000) -> 0 | AJ22: =IF(V22="",0,VLOOKUP(V22,Table_Data_Item!$C:$W,21,FALSE)*W22/10000) -> 0 | AK22: =IF(X22="",0,VLOOKUP(X22,Table_Data_Item!$C:$W,21,FALSE)*Y22/10000) -> 0 | AL22: =IF(Z22="",0,VLOOKUP(Z22,Table_Data_Item!$C:$W,21,FALSE)*AA22/10000) -> 0 | AM22: =IF(AB22="",0,VLOOKUP(AB22,Table_Data_Item!$C:$W,21,FALSE)*AC22/10000) -> 0

Sheet 설정
A1: 초당 보상 기준 | B1: 10
A2: 표준 플레이 타임 | B2: 60
A3: 등급 가중치 | B3: 0.2
A4: 결과 가중치 | B4: 0.5
A5: 랜덤 비율 | B5: 0.2

Sheet Table_Data_Item
A1: Id | B1: dev_name | C1: Name | D1: STR | E1: DESC | F1: Grade | G1: Type | H1: Slot_Idx | I1: SATK | J1: LATK | K1: DEF | L1: ASPD | M1: SPD | N1: HP | O1: Effect | P1: Effect_Value | Q1: Option_1 | R1: Option_2 | S1: Option_3 | T1: Option_4 | U1: Option_5 | V1: Is_Stack | W1: Price | X1: Coin_Price | Y1: Key | Z1: Key_Amount | AA1: Icon | AB1: Drop_1 | AC1: Drop_2 | AD1: Drop_3
A2: 30000 | B2: 빨간 물약 | C2: item_potion_heal_01 | D2: STR_ITEM_POTION_HEAL_01 | E2: STR_ITEM_POTION_HEAL_01_DESC | F2: 0 | G2: Potion | H2: 0 | I2: 0 | J2: 0 | K2: 0 | L2: 0 | M2: 0 | N2: 0 | O2: ADD_HP | P2: 20 | V2: TRUE | W2: 200 | X2: 0 | Z2: 0 | AA2: icon_item_0001
A3: 30001 | B3: 주황 물약 | C3: item_potion_heal_02 | D3: STR_ITEM_POTION_HEAL_02 | E3: STR_ITEM_POTION_HEAL_02_DESC | F3: 0 | G3: Potion | H3: 0 | I3: 0 | J3: 0 | K3: 0 | L3: 0 | M3: 0 | N3: 0 | O3: ADD_HP | P3: 60 | V3: TRUE | W3: 600 | X3: 0 | Z3: 0 | AA3: icon_item_0002
A4: 30002 | B4: 보라 물약 | C4: item_potion_heal_03 | D4: STR_ITEM_POTION_HEAL_03 | E4: STR_ITEM_POTION_HEAL_03_DESC | F4: 0 | G4: Potion | H4: 0 | I4: 0 | J4: 0 | K4: 0 | L4: 0 | M4: 0 | N4: 0 | O4: ADD_HP | P4: 100 | V4: TRUE | W4: 1000 | X4: 0 | Z4: 0 | AA4: icon_item_0003
A5: 30003 | B5: 노랑 물약 | C5: item_potion_heal_04 | D5: STR_ITEM_POTION_HEAL_04 | E5: STR_ITEM_POTION_HEAL_04_DESC | F5: 0 | G5: Potion | H5: 0 | I5: 0 | J5: 0 | K5: 0 | L5: 0 | M5: 0 | N5: 0 | O5: ADD_HP | P5: 150 | V5: TRUE | W5: 1500 | X5: 0 | Z5: 0 | AA5: icon_item_0004
A6: 30004 | B6: 하얀 물약 | C6: item_potion_heal_05 | D6: STR_ITEM_POTION_HEAL_05 | E6: STR_ITEM_POTION_HEAL_05_DESC | F6: 0 | G6: Potion | H6: 0 | I6: 0 | J6: 0 | K6: 0 | L6: 0 | M6: 0 | N6: 0 | O6: ADD_HP | P6: 200 | V6: TRUE | W6: 2000 | X6: 0 | Z6: 0 | AA6: icon_item_0005
A7: 31000 | B7: 낡은 옷 | C7: item_equip_n_ar_01 | D7: STR_ITEM_EQUIP_N_AR_01 | E7: STR_ITEM_EQUIP_N_AR_01_DESC | F7: 1 | G7: Equip | H7: 2 | I7: 0 | J7: 0 | K7: 2 | L7: 0 | M7: 0 | N7: 0 | O7: None | P7: 0 | V7: FALSE | W7: 10 | X7: 0 | Z7: 0 | AA7: icon_item_1000
A8: 31001 | B8: 가죽 갑옷 | C8: item_equip_n_ar_02 | D8: STR_ITEM_EQUIP_N_AR_02 | E8: STR_ITEM_EQUIP_N_AR_02_DESC | F8: 1 | G8: Equip | H8: 2 | I8: 0 | J8: 0 | K8: 4 | L8: 0 | M8: 0 | N8: 0 | O8: None | P8: 0 | V8: FALSE | W8: 5000 | X8: 0 | Z8: 0 | AA8: icon_item_1001
A9: 31002 | B9: 강화 가죽 갑옷 | C9: item_equip_n_ar_03 | D9: STR_ITEM_EQUIP_N_AR_03 | E9: STR_ITEM_EQUIP_N_AR_03_DESC | F9: 1 | G9: Equip | H9: 2 | I9: 0 | J9: 0 | K9: 5 | L9: 0 | M9: 0 | N9: 0 | O9: None | P9: 0 | V9: FALSE | W9: 7500 | X9: 0 | Z9: 0 | AA9: icon_item_1002
A10: 31003 | B10: 레어 가죽 갑옷 | C10: item_equip_n_ar_04 | D10: STR_ITEM_EQUIP_N_AR_04 | E10: STR_ITEM_EQUIP_N_AR_04_DESC | F10: 1 | G10: Equip | H10: 2 | I10: 0 | J10: 0 | K10: 5 | L10: 0 | M10: 0 | N10: 0 | O10: None | P10: 0 | Q10: option_pow_01 | R10: option_dex_01 | S10: option_int_01 | T10: option_con_01 | U10: option_luc_01 | V10: FALSE | W10: 10000 | X10: 0 | Z10: 0 | AA10: icon_item_1003
A11: 31004 | B11: 천 옷 | C11: item_equip_n_ar_05 | D11: STR_ITEM_EQUIP_N_AR_05 | E11: STR_ITEM_EQUIP_N_AR_05_DESC | F11: 1 | G11: Equip | H11: 2 | I11: 0 | J11: 0 | K11: 2 | L11: 0 | M11: 0 | N11: 20 | O11: None | P11: 0 | V11: FALSE | W11: 5000 | X11: 0 | Z11: 0 | AA11: icon_item_1201
A12: 31005 | B12: 강화 천 옷 | C12: item_equip_n_ar_06 | D12: STR_ITEM_EQUIP_N_AR_06 | E12: STR_ITEM_EQUIP_N_AR_06_DESC | F12: 1 | G12: Equip | H12: 2 | I12: 0 | J12: 0 | K12: 3 | L12: 0 | M12: 0 | N12: 30 | O12: None | P12: 0 | V12: FALSE | W12: 7500 | X12: 0 | Z12: 0 | AA12: icon_item_1202
A13: 31006 | B13: 레어 천 옷 | C13: item_equip_n_ar_07 | D13: STR_ITEM_EQUIP_N_AR_07 | E13: STR_ITEM_EQUIP_N_AR_07_DESC | F13: 1 | G13: Equip | H13: 2 | I13: 0 | J13: 0 | K13: 3 | L13: 0 | M13: 0 | N13: 30 | O13: None | P13: 0 | Q13: option_pow_01 | R13: option_dex_01 | S13: option_int_01 | T13: option_con_01 | U13: option_luc_01 | V13: FALSE | W13: 10000 | X13: 0 | Z13: 0 | AA13: icon_item_1203
A14: 31007 | B14: 구리 갑옷 | C14: item_equip_n_ar_08 | D14: STR_ITEM_EQUIP_N_AR_08 | E14: STR_ITEM_EQUIP_N_AR_08_DESC | F14: 2 | G14: Equip | H14: 2 | I14: 0 | J14: 0 | K14: 8 | L14: 0 | M14: 0 | N14: 0 | O14: None | P14: 0 | V14: FALSE | W14: 25000 | X14: 0 | Z14: 0 | AA14: icon_item_1003
A15: 31008 | B15: 강화 구리 갑옷 | C15: item_equip_n_ar_09 | D15: STR_ITEM_EQUIP_N_AR_09 | E15: STR_ITEM_EQUIP_N_AR_09_DESC | F15: 2 | G15: Equip | H15: 2 | I15: 0 | J15: 0 | K15: 9 | L15: 0 | M15: 0 | N15: 0 | O15: None | P15: 0 | V15: FALSE | W15: 37500 | X15: 0 | Z15: 0 | AA15: icon_item_1004
A16: 31009 | B16: 레어 구리 갑옷 | C16: item_equip_n_ar_10 | D16: STR_ITEM_EQUIP_N_AR_10 | E16: STR_ITEM_EQUIP_N_AR_10_DESC | F16: 2 | G16: Equip | H16: 2 | I16: 0 | J16: 0 | K16: 9 | L16: 0 | M16: 0 | N16: 0 | O16: None | P16: 0 | Q16: option_pow_01 | R16: option_dex_01 | S16: option_int_01 | T16: option_con_01 | U16: option_luc_01 | V16: FALSE | W16: 50000 | X16: 0 | Z16: 0 | AA16: icon_item_1004
A17: 31010 | B17: 가죽 옷 | C17: item_equip_n_ar_11 | D17: STR_ITEM_EQUIP_N_AR_11 | E17: STR_ITEM_EQUIP_N_AR_11_DESC | F17: 2 | G17: Equip | H17: 2 | I17: 0 | J17: 0 | K17: 4 | L17: 0 | M17: 0 | N17: 40 | O17: None | P17: 0 | V17: FALSE | W17: 25000 | X17: 0 | Z17: 0 | AA17: icon_item_1204
A18: 31011 | B18: 강화 가죽 옷 | C18: item_equip_n_ar_12 | D18: STR_ITEM_EQUIP_N_AR_12 | E18: STR_ITEM_EQUIP_N_AR_12_DESC | F18: 2 | G18: Equip | H18: 2 | I18: 0 | J18: 0 | K18: 5 | L18: 0 | M18: 0 | N18: 50 | O18: None | P18: 0 | V18: FALSE | W18: 37500 | X18: 0 | Z18: 0 | AA18: icon_item_1205
A19: 31012 | B19: 레어 가죽 옷 | C19: item_equip_n_ar_13 | D19: STR_ITEM_EQUIP_N_AR_13 | E19: STR_ITEM_EQUIP_N_AR_13_DESC | F19: 2 | G19: Equip | H19: 2 | I19: 0 | J19: 0 | K19: 5 | L19: 0 | M19: 0 | N19: 50 | O19: None | P19: 0 | Q19: option_pow_01 | R19: option_dex_01 | S19: option_int_01 | T19: option_con_01 | U19: option_luc_01 | V19: FALSE | W19: 50000 | X19: 0 | Z19: 0 | AA19: icon_item_1206
A20: 31013 | B20: 황동 갑옷 | C20: item_equip_n_ar_14 | D20: STR_ITEM_EQUIP_N_AR_14 | E20: STR_ITEM_EQUIP_N_AR_14_DESC | F20: 3 | G20: Equip | H20: 2 | I20: 0 | J20: 0 | K20: 12 | L20: 0 | M20: 0 | N20: 0 | O20: None | P20: 0 | V20: FALSE | W20: 125000 | X20: 0 | Z20: 0 | AA20: icon_item_1005
A21: 31014 | B21: 강화 황동 갑옷 | C21: item_equip_n_ar_15 | D21: STR_ITEM_EQUIP_N_AR_15 | E21: STR_ITEM_EQUIP_N_AR_15_DESC | F21: 3 | G21: Equip | H21: 2 | I21: 0 | J21: 0 | K21: 13 | L21: 0 | M21: 0 | N21: 0 | O21: None | P21: 0 | V21: FALSE | W21: 187500 | X21: 0 | Z21: 0 | AA21: icon_item_1006
A22: 31015 | B22: 레어 황동 갑옷 | C22: item_equip_n_ar_16 | D22: STR_ITEM_EQUIP_N_AR_16 | E22: STR_ITEM_EQUIP_N_AR_16_DESC | F22: 3 | G22: Equip | H22: 2 | I22: 0 | J22: 0 | K22: 13 | L22: 0 | M22: 0 | N22: 0 | O22: None | P22: 0 | Q22: option_pow_01 | R22: option_dex_01 | S22: option_int_01 | T22: option_con_01 | U22: option_luc_01 | V22: FALSE | W22: 250000 | X22: 0 | Z22: 0 | AA22: icon_item_1006
A23: 31016 | B23: 무복 | C23: item_equip_n_ar_17 | D23: STR_ITEM_EQUIP_N_AR_17 | E23: STR_ITEM_EQUIP_N_AR_17_DESC | F23: 3 | G23: Equip | H23: 2 | I23: 0 | J23: 0 | K23: 6 | L23: 0 | M23: 0 | N23: 60 | O23: None | P23: 0 | V23: FALSE | W23: 125000 | X23: 0 | Z23: 0 | AA23: icon_item_1207
A24: 31017 | B24: 장식된 무복 | C24: item_equip_n_ar_18 | D24: STR_ITEM_EQUIP_N_AR_18 | E24: STR_ITEM_EQUIP_N_AR_18_DESC | F24: 3 | G24: Equip | H24: 2 | I24: 0 | J24: 0 | K24: 7 | L24: 0 | M24: 0 | N24: 70 | O24: None | P24: 0 | V24: FALSE | W24: 187500 | X24: 0 | Z24: 0 | AA24: icon_item_1208
A25: 31018 | B25: 레어 무복 | C25: item_equip_n_ar_19 | D25: STR_ITEM_EQUIP_N_AR_19 | E25: STR_ITEM_EQUIP_N_AR_19_DESC | F25: 3 | G25: Equip | H25: 2 | I25: 0 | J25: 0 | K25: 7 | L25: 0 | M25: 0 | N25: 70 | O25: None | P25: 0 | Q25: option_pow_01 | R25: option_dex_01 | S25: option_int_01 | T25: option_con_01 | U25: option_luc_01 | V25: FALSE | W25: 250000 | X25: 0 | Z25: 0 | AA25: icon_item_1209
A26: 31019 | B26: 철 갑옷 | C26: item_equip_n_ar_20 | D26: STR_ITEM_EQUIP_N_AR_20 | E26: STR_ITEM_EQUIP_N_AR_20_DESC | F26: 4 | G26: Equip | H26: 2 | I26: 0 | J26: 0 | K26: 16 | L26: 0 | M26: 0 | N26: 0 | O26: None | P26: 0 | V26: FALSE | W26: 625000 | X26: 0 | Z26: 0 | AA26: icon_item_1005
A27: 31020 | B27: 강화 철 갑옷 | C27: item_equip_n_ar_21 | D27: STR_ITEM_EQUIP_N_AR_21 | E27: STR_ITEM_EQUIP_N_AR_21_DESC | F27: 4 | G27: Equip | H27: 2 | I27: 0 | J27: 0 | K27: 17 | L27: 0 | M27: 0 | N27: 0 | O27: None | P27: 0 | V27: FALSE | W27: 937500 | X27: 0 | Z27: 0 | AA27: icon_item_1006
A28: 31021 | B28: 레어 철 갑옷 | C28: item_equip_n_ar_22 | D28: STR_ITEM_EQUIP_N_AR_22 | E28: STR_ITEM_EQUIP_N_AR_22_DESC | F28: 4 | G28: Equip | H28: 2 | I28: 0 | J28: 0 | K28: 17 | L28: 0 | M28: 0 | N28: 0 | O28: None | P28: 0 | Q28: option_pow_01 | R28: option_dex_01 | S28: option_int_01 | T28: option_con_01 | U28: option_luc_01 | V28: FALSE | W28: 1250000 | X28: 0 | Z28: 0 | AA28: icon_item_1006
A29: 31022 | B29: 법사 옷 | C29: item_equip_n_ar_23 | D29: STR_ITEM_EQUIP_N_AR_23 | E29: STR_ITEM_EQUIP_N_AR_23_DESC | F29: 4 | G29: Equip | H29: 2 | I29: 0 | J29: 0 | K29: 8 | L29: 0 | M29: 0 | N29: 80 | O29: None | P29: 0 | V29: FALSE | W29: 625000 | X29: 0 | Z29: 0 | AA29: icon_item_1207
A30: 31023 | B30: 장식된 법사 옷 | C30: item_equip_n_ar_24 | D30: STR_ITEM_EQUIP_N_AR_24 | E30: STR_ITEM_EQUIP_N_AR_24_DESC | F30: 4 | G30: Equip | H30: 2 | I30: 0 | J30: 0 | K30: 9 | L30: 0 | M30: 0 | N30: 90 | O30: None | P30: 0 | V30: FALSE | W30: 937500 | X30: 0 | Z30: 0 | AA30: icon_item_1208
A31: 31024 | B31: 레어 법사 옷 | C31: item_equip_n_ar_25 | D31: STR_ITEM_EQUIP_N_AR_25 | E31: STR_ITEM_EQUIP_N_AR_25_DESC | F31: 4 | G31: Equip | H31: 2 | I31: 0 | J31: 0 | K31: 9 | L31: 0 | M31: 0 | N31: 90 | O31: None | P31: 0 | Q31: option_pow_01 | R31: option_dex_01 | S31: option_int_01 | T31: option_con_01 | U31: option_luc_01 | V31: FALSE | W31: 1250000 | X31: 0 | Z31: 0 | AA31: icon_item_1209
A32: 32000 | B32: 구리 반지 | C32: item_equip_n_ac_01 | D32: STR_ITEM_EQUIP_N_AC_01 | E32: STR_ITEM_EQUIP_N_AC_01_DESC | F32: 1 | G32: Equip | H32: 0 | I32: 0 | J32: 0 | K32: 0 | L32: 10 | M32: 0 | N32: 0 | O32: None | P32: 0 | V32: FALSE | W32: 10 | X32: 0 | Z32: 0 | AA32: icon_item_2000
A33: 32001 | B33: 은 반지 | C33: item_equip_n_ac_02 | D33: STR_ITEM_EQUIP_N_AC_02 | E33: STR_ITEM_EQUIP_N_AC_02_DESC | F33: 1 | G33: Equip | H33: 0 | I33: 0 | J33: 0 | K33: 0 | L33: 15 | M33: 0 | N33: 0 | O33: None | P33: 0 | V33: FALSE | W33: 6250 | X33: 0 | Z33: 0 | AA33: icon_item_2001
A34: 32002 | B34: 금 반지 | C34: item_equip_n_ac_03 | D34: STR_ITEM_EQUIP_N_AC_03 | E34: STR_ITEM_EQUIP_N_AC_03_DESC | F34: 1 | G34: Equip | H34: 0 | I34: 0 | J34: 0 | K34: 0 | L34: 20 | M34: 0 | N34: 0 | O34: None | P34: 0 | V34: FALSE | W34: 9370 | X34: 0 | Z34: 0 | AA34: icon_item_2002
A35: 32003 | B35: 마법사의 반지 | C35: item_equip_n_ac_04 | D35: STR_ITEM_EQUIP_N_AC_04 | E35: STR_ITEM_EQUIP_N_AC_04_DESC | F35: 1 | G35: Equip | H35: 0 | I35: 0 | J35: 0 | K35: 0 | L35: 22 | M35: 0 | N35: 0 | O35: None | P35: 0 | Q35: option_pow_01 | R35: option_dex_01 | S35: option_int_01 | T35: option_con_01 | U35: option_luc_01 | V35: FALSE | W35: 12500 | X35: 0 | Z35: 0 | AA35: icon_item_2003
A36: 32004 | B36: 백금 반지 | C36: item_equip_n_ac_05 | D36: STR_ITEM_EQUIP_N_AC_05 | E36: STR_ITEM_EQUIP_N_AC_05_DESC | F36: 2 | G36: Equip | H36: 0 | I36: 0 | J36: 0 | K36: 0 | L36: 25 | M36: 0 | N36: 0 | O36: None | P36: 0 | V36: FALSE | W36: 31250 | X36: 0 | Z36: 0 | AA36: icon_item_2001
A37: 32005 | B37: 순금 반지 | C37: item_equip_n_ac_06 | D37: STR_ITEM_EQUIP_N_AC_06 | E37: STR_ITEM_EQUIP_N_AC_06_DESC | F37: 2 | G37: Equip | H37: 0 | I37: 0 | J37: 0 | K37: 0 | L37: 30 | M37: 0 | N37: 0 | O37: None | P37: 0 | V37: FALSE | W37: 46850 | X37: 0 | Z37: 0 | AA37: icon_item_2002
A38: 32006 | B38: 붉은 마법 반지 | C38: item_equip_n_ac_07 | D38: STR_ITEM_EQUIP_N_AC_07 | E38: STR_ITEM_EQUIP_N_AC_07_DESC | F38: 2 | G38: Equip | H38: 0 | I38: 0 | J38: 0 | K38: 0 | L38: 32 | M38: 0 | N38: 0 | O38: None | P38: 0 | Q38: option_pow_01 | R38: option_dex_01 | S38: option_int_01 | T38: option_con_01 | U38: option_luc_01 | V38: FALSE | W38: 62500 | X38: 0 | Z38: 0 | AA38: icon_item_2003
A39: 32007 | B39: 사파이어 반지 | C39: item_equip_n_ac_08 | D39: STR_ITEM_EQUIP_N_AC_08 | E39: STR_ITEM_EQUIP_N_AC_08_DESC | F39: 3 | G39: Equip | H39: 0 | I39: 0 | J39: 0 | K39: 0 | L39: 35 | M39: 0 | N39: 0 | O39: None | P39: 0 | V39: FALSE | W39: 156250 | X39: 0 | Z39: 0 | AA39: icon_item_2001
A40: 32008 | B40: 루비 반지 | C40: item_equip_n_ac_09 | D40: STR_ITEM_EQUIP_N_AC_09 | E40: STR_ITEM_EQUIP_N_AC_09_DESC | F40: 3 | G40: Equip | H40: 0 | I40: 0 | J40: 0 | K40: 0 | L40: 40 | M40: 0 | N40: 0 | O40: None | P40: 0 | V40: FALSE | W40: 234250 | X40: 0 | Z40: 0 | AA40: icon_item_2002
...
