Workbook

Sheet 맵 밸런스
A1: 맵 ID | B1: 이름 | C1: 등급 | D1: DPS | E1: 이동속도 | F1: 거리 | G1: 방향전환 | H1: 대화횟수 | I1: 상자,함정,지나치는몹 | J1: 몬스터 | K1: 골드 | L1: 실버 | M1: 수동 설정
A2: 50000 | B2: =VLOOKUP($A2,Table_Data_Map!$A:$F,2,FALSE) -> 튜토리얼 1 | C2: =VLOOKUP($A2,Table_Data_Map!$A:$F,6,FALSE) -> 1 | D2: =VLOOKUP($C2,표준캐릭터설정!$A:$E,4,FALSE) -> 7.8125 | E2: =VLOOKUP($C2,표준캐릭터설정!$A:$E,5,FALSE) -> 75 | F2: 4 | G2: 0 | H2: 0 | I2: 0 | J2: 0 | K2: =$L2+1 -> 8.9 | L2: =INT((10 - ((F2*32/E2) + (G2 * 0.3) + (H2 / 8) + (I2 * 0.7) + (J2 * 4)) - 0.3) * 10) * 0.1 -> 7.9
A3: 50001 | B3: =VLOOKUP($A3,Table_Data_Map!$A:$F,2,FALSE) -> 튜토리얼 2 | C3: =VLOOKUP($A3,Table_Data_Map!$A:$F,6,FALSE) -> 1 | D3: =VLOOKUP($C3,표준캐릭터설정!$A:$E,4,FALSE) -> 7.8125 | E3: =VLOOKUP($C3,표준캐릭터설정!$A:$E,5,FALSE) -> 75 | F3: 3 | G3: 0 | H3: 0 | I3: 0 | J3: 0 | K3: =$L3+1 -> 9.4 | L3: =INT((10 - ((F3*32/E3) + (G3 * 0.3) + (H3 / 8) + (I3 * 0.7) + (J3 * 4)) - 0.3) * 10) * 0.1 -> 8.4
A4: 50002 | B4: =VLOOKUP($A4,Table_Data_Map!$A:$F,2,FALSE) -> 튜토리얼 3 | C4: =VLOOKUP($A4,Table_Data_Map!$A:$F,6,FALSE) -> 1 | D4: =VLOOKUP($C4,표준캐릭터설정!$A:$E,4,FALSE) -> 7.8125 | E4: =VLOOKUP($C4,표준캐릭터설정!$A:$E,5,FALSE) -> 75 | F4: 4 | G4: 0 | H4: 0 | I4: 0 | J4: 0 | K4: =$L4+1 -> 8.9 | L4: =INT((10 - ((F4*32/E4) + (G4 * 0.3) + (H4 / 8) + (I4 * 0.7) + (J4 * 4)) - 0.3) * 10) * 0.1 -> 7.9
A5: 50003 | B5: =VLOOKUP($A5,Table_Data_Map!$A:$F,2,FALSE) -> 튜토리얼 4 | C5: =VLOOKUP($A5,Table_Data_Map!$A:$F,6,FALSE) -> 1 | D5: =VLOOKUP($C5,표준캐릭터설정!$A:$E,4,FALSE) -> 7.8125 | E5: =VLOOKUP($C5,표준캐릭터설정!$A:$E,5,FALSE) -> 75 | F5: 4 | G5: 0 | H5: 0 | I5: 0 | J5: 0 | K5: =$L5+1 -> 8.9 | L5: =INT((10 - ((F5*32/E5) + (G5 * 0.3) + (H5 / 8) + (I5 * 0.7) + (J5 * 4)) - 0.3) * 10) * 0.1 -> 7.9
A6: 50004 | B6: =VLOOKUP($A6,Table_Data_Map!$A:$F,2,FALSE) -> 숲 속 마을 입구 | C6: =VLOOKUP($A6,Table_Data_Map!$A:$F,6,FALSE) -> 2 | D6: =VLOOKUP($C6,표준캐릭터설정!$A:$E,4,FALSE) -> 18.404908 | E6: =VLOOKUP($C6,표준캐릭터설정!$A:$E,5,FALSE) -> 83 | F6: 8 | G6: 0 | H6: 0 | I6: 0 | J6: 0 | K6: =$L6+1 -> 7.6 | L6: =INT((10 - ((F6*32/E6) + (G6 * 0.3) + (H6 / 8) + (I6 * 0.7) + (J6 * 4)) - 0.3) * 10) * 0.1 -> 6.6
A7: 50005 | B7: =VLOOKUP($A7,Table_Data_Map!$A:$F,2,FALSE) -> 숲 속 마을 여관 | C7: =VLOOKUP($A7,Table_Data_Map!$A:$F,6,FALSE) -> 2 | D7: =VLOOKUP($C7,표준캐릭터설정!$A:$E,4,FALSE) -> 18.404908 | E7: =VLOOKUP($C7,표준캐릭터설정!$A:$E,5,FALSE) -> 83 | F7: 9 | G7: 2 | H7: 0 | I7: 0 | J7: 0 | K7: =$L7+1 -> 6.6 | L7: =INT((10 - ((F7*32/E7) + (G7 * 0.3) + (H7 / 8) + (I7 * 0.7) + (J7 * 4)) - 0.3) * 10) * 0.1 -> 5.6
A8: 50006 | B8: =VLOOKUP($A8,Table_Data_Map!$A:$F,2,FALSE) -> 이사벨과 대화 | C8: =VLOOKUP($A8,Table_Data_Map!$A:$F,6,FALSE) -> 2 | D8: =VLOOKUP($C8,표준캐릭터설정!$A:$E,4,FALSE) -> 18.404908 | E8: =VLOOKUP($C8,표준캐릭터설정!$A:$E,5,FALSE) -> 83 | F8: 3 | G8: 0 | H8: 2 | I8: 0 | J8: 0 | K8: =$L8+1 -> 9.2 | L8: =INT((10 - ((F8*32/E8) + (G8 * 0.3) + (H8 / 8) + (I8 * 0.7) + (J8 * 4)) - 0.3) * 10) * 0.1 -> 8.2
A9: 50007 | B9: =VLOOKUP($A9,Table_Data_Map!$A:$F,2,FALSE) -> 촌장님 집으로 | C9: =VLOOKUP($A9,Table_Data_Map!$A:$F,6,FALSE) -> 2 | D9: =VLOOKUP($C9,표준캐릭터설정!$A:$E,4,FALSE) -> 18.404908 | E9: =VLOOKUP($C9,표준캐릭터설정!$A:$E,5,FALSE) -> 83 | F9: 7 | G9: 1 | H9: 0 | I9: 0 | J9: 0 | K9: =$L9+1 -> 7.7 | L9: =INT((10 - ((F9*32/E9) + (G9 * 0.3) + (H9 / 8) + (I9 * 0.7) + (J9 * 4)) - 0.3) * 10) * 0.1 -> 6.7
A10: 50008 | B10: =VLOOKUP($A10,Table_Data_Map!$A:$F,2,FALSE) -> 촌장님과 대화 | C10: =VLOOKUP($A10,Table_Data_Map!$A:$F,6,FALSE) -> 2 | D10: =VLOOKUP($C10,표준캐릭터설정!$A:$E,4,FALSE) -> 18.404908 | E10: =VLOOKUP($C10,표준캐릭터설정!$A:$E,5,FALSE) -> 83 | F10: 7 | G10: 2 | H10: 30 | I10: 0 | J10: 0 | K10: =$L10+1 -> 3.6 | L10: =INT((10 - ((F10*32/E10) + (G10 * 0.3) + (H10 / 8) + (I10 * 0.7) + (J10 * 4)) - 0.3) * 10) * 0.1 -> 2.6
A11: 50009 | B11: =VLOOKUP($A11,Table_Data_Map!$A:$F,2,FALSE) -> 숲 속 마을 북쪽으로 | C11: =VLOOKUP($A11,Table_Data_Map!$A:$F,6,FALSE) -> 2 | D11: =VLOOKUP($C11,표준캐릭터설정!$A:$E,4,FALSE) -> 18.404908 | E11: =VLOOKUP($C11,표준캐릭터설정!$A:$E,5,FALSE) -> 83 | F11: 10 | G11: 1 | H11: 0 | I11: 0 | J11: 0 | K11: =$L11+1 -> 6.5 | L11: =INT((10 - ((F11*32/E11) + (G11 * 0.3) + (H11 / 8) + (I11 * 0.7) + (J11 * 4)) - 0.3) * 10) * 0.1 -> 5.5
A12: 50010 | B12: =VLOOKUP($A12,Table_Data_Map!$A:$F,2,FALSE) -> 슬라임 처치 | C12: =VLOOKUP($A12,Table_Data_Map!$A:$F,6,FALSE) -> 2 | D12: =VLOOKUP($C12,표준캐릭터설정!$A:$E,4,FALSE) -> 18.404908 | E12: =VLOOKUP($C12,표준캐릭터설정!$A:$E,5,FALSE) -> 83 | F12: 3 | G12: 0 | H12: 0 | I12: 0 | J12: 1 | K12: =$L12+1 -> 5.5 | L12: =INT((10 - ((F12*32/E12) + (G12 * 0.3) + (H12 / 8) + (I12 * 0.7) + (J12 * 4)) - 0.3) * 10) * 0.1 -> 4.5
A13: 50011 | B13: =VLOOKUP($A13,Table_Data_Map!$A:$F,2,FALSE) -> 훈련소로 이동 1 | C13: =VLOOKUP($A13,Table_Data_Map!$A:$F,6,FALSE) -> 2 | D13: =VLOOKUP($C13,표준캐릭터설정!$A:$E,4,FALSE) -> 18.404908 | E13: =VLOOKUP($C13,표준캐릭터설정!$A:$E,5,FALSE) -> 83 | F13: 8 | G13: 2 | H13: 0 | I13: 0 | J13: 0 | K13: =$L13+1 -> 7 | L13: =INT((10 - ((F13*32/E13) + (G13 * 0.3) + (H13 / 8) + (I13 * 0.7) + (J13 * 4)) - 0.3) * 10) * 0.1 -> 6
... A29: 50027 | B29: =VLOOKUP($A29,Table_Data_Map!$A:$F,2,FALSE) -> 숨겨진 방으로 이동 | C29: =VLOOKUP($A29,Table_Data_Map!$A:$F,6,FALSE) -> 2 | D29: =VLOOKUP($C29,표준캐릭터설정!$A:$E,4,FALSE) -> 18.404908 | E29: =VLOOKUP($C29,표준캐릭터설정!$A:$E,5,FALSE) -> 83 | F29: 7 | G29: 1 | H29: 0 | I29: 0 | J29: 0 | K29: =$L29+1 -> 7.7 | L29: =INT((10 - ((F29*32/E29) + (G29 * 0.3) + (H29 / 8) + (I29 * 0.7) + (J29 * 4)) - 0.3) * 10) * 0.1 -> 6.7
A30: 50028 | B30: =VLOOKUP($A30,Table_Data_Map!$A:$F,2,FALSE) -> 숨겨진 방 | C30: =VLOOKUP($A30,Table_Data_Map!$A:$F,6,FALSE) -> 2 | D30: =VLOOKUP($C30,표준캐릭터설정!$A:$E,4,FALSE) -> 18.404908 | E30: =VLOOKUP($C30,표준캐릭터설정!$A:$E,5,FALSE) -> 83 | F30: 4 | G30: 0 | H30: 0 | I30: 0 | J30: 0 | K30: 1 | L30: 10 | M30: TRUE
A31: 50029 | B31: =VLOOKUP($A31,Table_Data_Map!$A:$F,2,FALSE) -> 동쪽 숲으로 | C31: =VLOOKUP($A31,Table_Data_Map!$A:$F,6,FALSE) -> 2 | D31: =VLOOKUP($C31,표준캐릭터설정!$A:$E,4,FALSE) -> 18.404908 | E31: =VLOOKUP($C31,표준캐릭터설정!$A:$E,5,FALSE) -> 83 | F31: 5 | G31: 1 | H31: 0 | I31: 0 | J31: 0 | K31: =$L31+1 -> 8.4 | L31: =INT((10 - ((F31*32/E31) + (G31 * 0.3) + (H31 / 8) + (I31 * 0.7) + (J31 * 4)) - 0.3) * 10) * 0.1 -> 7.4
A32: 50030 | B32: =VLOOKUP($A32,Table_Data_Map!$A:$F,2,FALSE) -> 동쪽 숲 1 | C32: =VLOOKUP($A32,Table_Data_Map!$A:$F,6,FALSE) -> 3 | D32: =VLOOKUP($C32,표준캐릭터설정!$A:$E,4,FALSE) -> 34.334764 | E32: =VLOOKUP($C32,표준캐릭터설정!$A:$E,5,FALSE) -> 91 | F32: 14 | G32: 6 | H32: 0 | I32: 0 | J32: 0 | K32: =$L32+1 -> 3.9 | L32: =INT((10 - ((F32*32/E32) + (G32 * 0.3) + (H32 / 8) + (I32 * 0.7) + (J32 * 4)) - 0.3) * 10) * 0.1 -> 2.9
A33: 50031 | B33: =VLOOKUP($A33,Table_Data_Map!$A:$F,2,FALSE) -> 동쪽 숲 2 | C33: =VLOOKUP($A33,Table_Data_Map!$A:$F,6,FALSE) -> 3 | D33: =VLOOKUP($C33,표준캐릭터설정!$A:$E,4,FALSE) -> 34.334764 | E33: =VLOOKUP($C33,표준캐릭터설정!$A:$E,5,FALSE) -> 91 | F33: 13 | G33: 5 | H33: 0 | I33: 0 | J33: 0 | K33: =$L33+1 -> 4.6 | L33: =INT((10 - ((F33*32/E33) + (G33 * 0.3) + (H33 / 8) + (I33 * 0.7) + (J33 * 4)) - 0.3) * 10) * 0.1 -> 3.6
A34: 50032 | B34: =VLOOKUP($A34,Table_Data_Map!$A:$F,2,FALSE) -> 동쪽 숲 3 | C34: =VLOOKUP($A34,Table_Data_Map!$A:$F,6,FALSE) -> 3 | D34: =VLOOKUP($C34,표준캐릭터설정!$A:$E,4,FALSE) -> 34.334764 | E34: =VLOOKUP($C34,표준캐릭터설정!$A:$E,5,FALSE) -> 91 | F34: 8 | G34: 2 | H34: 0 | I34: 0 | J34: 0 | K34: =$L34+1 -> 7.2 | L34: =INT((10 - ((F34*32/E34) + (G34 * 0.3) + (H34 / 8) + (I34 * 0.7) + (J34 * 4)) - 0.3) * 10) * 0.1 -> 6.2
A35: 50033 | B35: =VLOOKUP($A35,Table_Data_Map!$A:$F,2,FALSE) -> 동쪽 숲 4 | C35: =VLOOKUP($A35,Table_Data_Map!$A:$F,6,FALSE) -> 3 | D35: =VLOOKUP($C35,표준캐릭터설정!$A:$E,4,FALSE) -> 34.334764 | E35: =VLOOKUP($C35,표준캐릭터설정!$A:$E,5,FALSE) -> 91 | F35: 17 | G35: 7 | H35: 0 | I35: 0 | J35: 0 | K35: =$L35+1 -> 2.6 | L35: =INT((10 - ((F35*32/E35) + (G35 * 0.3) + (H35 / 8) + (I35 * 0.7) + (J35 * 4)) - 0.3) * 10) * 0.1 -> 1.6
A36: 50034 | B36: =VLOOKUP($A36,Table_Data_Map!$A:$F,2,FALSE) -> 동쪽 숲 5 | C36: =VLOOKUP($A36,Table_Data_Map!$A:$F,6,FALSE) -> 3 | D36: =VLOOKUP($C36,표준캐릭터설정!$A:$E,4,FALSE) -> 34.334764 | E36: =VLOOKUP($C36,표준캐릭터설정!$A:$E,5,FALSE) -> 91 | F36: 11 | G36: 2 | H36: 0 | I36: 0 | J36: 0 | K36: =$L36+1 -> 6.2 | L36: =INT((10 - ((F36*32/E36) + (G36 * 0.3) + (H36 / 8) + (I36 * 0.7) + (J36 * 4)) - 0.3) * 10) * 0.1 -> 5.2
A37: 50035 | B37: =VLOOKUP($A37,Table_Data_Map!$A:$F,2,FALSE) -> 동쪽 숲 6 | C37: =VLOOKUP($A37,Table_Data_Map!$A:$F,6,FALSE) -> 3 | D37: =VLOOKUP($C37,표준캐릭터설정!$A:$E,4,FALSE) -> 34.334764 | E37: =VLOOKUP($C37,표준캐릭터설정!$A:$E,5,FALSE) -> 91 | F37: 13 | G37: 3 | H37: 0 | I37: 0 | J37: 0 | K37: =$L37+1 -> 5.2 | L37: =INT((10 - ((F37*32/E37) + (G37 * 0.3) + (H37 / 8) + (I37 * 0.7) + (J37 * 4)) - 0.3) * 10) * 0.1 -> 4.2
A38: 50036 | B38: =VLOOKUP($A38,Table_Data_Map!$A:$F,2,FALSE) -> 동쪽 숲 7 | C38: =VLOOKUP($A38,Table_Data_Map!$A:$F,6,FALSE) -> 3 | D38: =VLOOKUP($C38,표준캐릭터설정!$A:$E,4,FALSE) -> 34.334764 | E38: =VLOOKUP($C38,표준캐릭터설정!$A:$E,5,FALSE) -> 91 | F38: 11 | G38: 2 | H38: 0 | I38: 0 | J38: 0 | K38: =$L38+1 -> 6.2 | L38: =INT((10 - ((F38*32/E38) + (G38 * 0.3) + (H38 / 8) + (I38 * 0.7) + (J38 * 4)) - 0.3) * 10) * 0.1 -> 5.2
A39: 50037 | B39: =VLOOKUP($A39,Table_Data_Map!$A:$F,2,FALSE) -> 광산 마을 입구 | C39: =VLOOKUP($A39,Table_Data_Map!$A:$F,6,FALSE) -> 3 | D39: =VLOOKUP($C39,표준캐릭터설정!$A:$E,4,FALSE) -> 34.334764 | E39: =VLOOKUP($C39,표준캐릭터설정!$A:$E,5,FALSE) -> 91 | F39: 9 | G39: 2 | H39: 0 | I39: 0 | J39: 0 | K39: =$L39+1 -> 6.9 | L39: =INT((10 - ((F39*32/E39) + (G39 * 0.3) + (H39 / 8) + (I39 * 0.7) + (J39 * 4)) - 0.3) * 10) * 0.1 -> 5.9
A40: 50038 | B40: =VLOOKUP($A40,Table_Data_Map!$A:$F,2,FALSE) -> 죽은 자의 동굴 입구 | C40: =VLOOKUP($A40,Table_Data_Map!$A:$F,6,FALSE) -> 3 | D40: =VLOOKUP($C40,표준캐릭터설정!$A:$E,4,FALSE) -> 34.334764 | E40: =VLOOKUP($C40,표준캐릭터설정!$A:$E,5,FALSE) -> 91 | F40: 5 | G40: 0 | H40: 0 | I40: 0 | J40: 0 | K40: =$L40+1 -> 8.9 | L40: =INT((10 - ((F40*32/E40) + (G40 * 0.3) + (H40 / 8) + (I40 * 0.7) + (J40 * 4)) - 0.3) * 10) * 0.1 -> 7.9
A41: 50039 | B41: =VLOOKUP($A41,Table_Data_Map!$A:$F,2,FALSE) -> 비밀의 동굴로 | C41: =VLOOKUP($A41,Table_Data_Map!$A:$F,6,FALSE) -> 3 | D41: =VLOOKUP($C41,표준캐릭터설정!$A:$E,4,FALSE) -> 34.334764 | E41: =VLOOKUP($C41,표준캐릭터설정!$A:$E,5,FALSE) -> 91 | F41: 13 | G41: 4 | H41: 0 | I41: 0 | J41: 0 | K41: =$L41+1 -> 4.9 | L41: =INT((10 - ((F41*32/E41) + (G41 * 0.3) + (H41 / 8) + (I41 * 0.7) + (J41 * 4)) - 0.3) * 10) * 0.1 -> 3.9
A42: 50040 | B42: =VLOOKUP($A42,Table_Data_Map!$A:$F,2,FALSE) -> 동쪽 숲 보물방 | C42: =VLOOKUP($A42,Table_Data_Map!$A:$F,6,FALSE) -> 3 | D42: =VLOOKUP($C42,표준캐릭터설정!$A:$E,4,FALSE) -> 34.334764 | E42: =VLOOKUP($C42,표준캐릭터설정!$A:$E,5,FALSE) -> 91 | F42: 4 | G42: 0 | H42: 0 | I42: 0 | J42: 0 | K42: 1 | L42: 10 | M42: TRUE
A43: 50041 | B43: =VLOOKUP($A43,Table_Data_Map!$A:$F,2,FALSE) -> 경비병 로빈과 대화 | C43: =VLOOKUP($A43,Table_Data_Map!$A:$F,6,FALSE) -> 3 | D43: =VLOOKUP($C43,표준캐릭터설정!$A:$E,4,FALSE) -> 34.334764 | E43: =VLOOKUP($C43,표준캐릭터설정!$A:$E,5,FALSE) -> 91 | F43: 9 | G43: 3 | H43: 5 | I43: 0 | J43: 0 | K43: =$L43+1 -> 6 | L43: =INT((10 - ((F43*32/E43) + (G43 * 0.3) + (H43 / 8) + (I43 * 0.7) + (J43 * 4)) - 0.3) * 10) * 0.1 -> 5
A44: 50042 | B44: =VLOOKUP($A44,Table_Data_Map!$A:$F,2,FALSE) -> 로빈의 고민 | C44: =VLOOKUP($A44,Table_Data_Map!$A:$F,6,FALSE) -> 3 | D44: =VLOOKUP($C44,표준캐릭터설정!$A:$E,4,FALSE) -> 34.334764 | E44: =VLOOKUP($C44,표준캐릭터설정!$A:$E,5,FALSE) -> 91 | F44: 9 | G44: 3 | H44: 5 | I44: 0 | J44: 0 | K44: =$L44+1 -> 6 | L44: =INT((10 - ((F44*32/E44) + (G44 * 0.3) + (H44 / 8) + (I44 * 0.7) + (J44 * 4)) - 0.3) * 10) * 0.1 -> 5
A45: 50043 | B45: =VLOOKUP($A45,Table_Data_Map!$A:$F,2,FALSE) -> 회색 늑대 처치 | C45: =VLOOKUP($A45,Table_Data_Map!$A:$F,6,FALSE) -> 3 | D45: =VLOOKUP($C45,표준캐릭터설정!$A:$E,4,FALSE) -> 34.334764 | E45: =VLOOKUP($C45,표준캐릭터설정!$A:$E,5,FALSE) -> 91 | F45: 9 | G45: 3 | H45: 5 | I45: 0 | J45: 0 | K45: =$L45+1 -> 6 | L45: =INT((10 - ((F45*32/E45) + (G45 * 0.3) + (H45 / 8) + (I45 * 0.7) + (J45 * 4)) - 0.3) * 10) * 0.1 -> 5
A46: 50044 | B46: =VLOOKUP($A46,Table_Data_Map!$A:$F,2,FALSE) -> 로빈의 선물 | C46: =VLOOKUP($A46,Table_Data_Map!$A:$F,6,FALSE) -> 3 | D46: =VLOOKUP($C46,표준캐릭터설정!$A:$E,4,FALSE) -> 34.334764 | E46: =VLOOKUP($C46,표준캐릭터설정!$A:$E,5,FALSE) -> 91 | F46: 9 | G46: 3 | H46: 5 | I46: 0 | J46: 0 | K46: =$L46+1 -> 6 | L46: =INT((10 - ((F46*32/E46) + (G46 * 0.3) + (H46 / 8) + (I46 * 0.7) + (J46 * 4)) - 0.3) * 10) * 0.1 -> 5
A47: 50045 | B47: =VLOOKUP($A47,Table_Data_Map!$A:$F,2,FALSE) -> 개발자의 방으로 | C47: =VLOOKUP($A47,Table_Data_Map!$A:$F,6,FALSE) -> 1 | D47: =VLOOKUP($C47,표준캐릭터설정!$A:$E,4,FALSE) -> 7.8125 | E47: =VLOOKUP($C47,표준캐릭터설정!$A:$E,5,FALSE) -> 75 | F47: 9 | G47: 3 | H47: 5 | I47: 0 | J47: 0 | K47: =$L47+1 -> 5.3 | L47: =INT((10 - ((F47*32/E47) + (G47 * 0.3) + (H47 / 8) + (I47 * 0.7) + (J47 * 4)) - 0.3) * 10) * 0.1 -> 4.3
A48: 50046 | B48: =VLOOKUP($A48,Table_Data_Map!$A:$F,2,FALSE) -> 개발자와 대화 1 | C48: =VLOOKUP($A48,Table_Data_Map!$A:$F,6,FALSE) -> 1 | D48: =VLOOKUP($C48,표준캐릭터설정!$A:$E,4,FALSE) -> 7.8125 | E48: =VLOOKUP($C48,표준캐릭터설정!$A:$E,5,FALSE) -> 75 | F48: 9 | G48: 3 | H48: 5 | I48: 0 | J48: 0 | K48: =$L48+1 -> 5.3 | L48: =INT((10 - ((F48*32/E48) + (G48 * 0.3) + (H48 / 8) + (I48 * 0.7) + (J48 * 4)) - 0.3) * 10) * 0.1 -> 4.3
A49: 50047 | B49: =VLOOKUP($A49,Table_Data_Map!$A:$F,2,FALSE) -> 개발자와 대화 2 | C49: =VLOOKUP($A49,Table_Data_Map!$A:$F,6,FALSE) -> 1 | D49: =VLOOKUP($C49,표준캐릭터설정!$A:$E,4,FALSE) -> 7.8125 | E49: =VLOOKUP($C49,표준캐릭터설정!$A:$E,5,FALSE) -> 75 | F49: 9 | G49: 3 | H49: 5 | I49: 0 | J49: 0 | K49: =$L49+1 -> 5.3 | L49: =INT((10 - ((F49*32/E49) + (G49 * 0.3) + (H49 / 8) + (I49 * 0.7) + (J49 * 4)) - 0.3) * 10) * 0.1 -> 4.3
A50: 50048 | B50: =VLOOKUP($A50,Table_Data_Map!$A:$F,2,FALSE) -> 개발자와 대화 3 | C50: =VLOOKUP($A50,Table_Data_Map!$A:$F,6,FALSE) -> 1 | D50: =VLOOKUP($C50,표준캐릭터설정!$A:$E,4,FALSE) -> 7.8125 | E50: =VLOOKUP($C50,표준캐릭터설정!$A:$E,5,FALSE) -> 75 | F50: 9 | G50: 3 | H50: 5 | I50: 0 | J50: 0 | K50: =$L50+1 -> 5.3 | L50: =INT((10 - ((F50*32/E50) + (G50 * 0.3) + (H50 / 8) + (I50 * 0.7) + (J50 * 4)) - 0.3) * 10) * 0.1 -> 4.3
A51: 50049 | B51: =VLOOKUP($A51,Table_Data_Map!$A:$F,2,FALSE) -> 시험 2 | C51: =VLOOKUP($A51,Table_Data_Map!$A:$F,6,FALSE) -> 1 | D51: =VLOOKUP($C51,표준캐릭터설정!$A:$E,4,FALSE) -> 7.8125 | E51: =VLOOKUP($C51,표준캐릭터설정!$A:$E,5,FALSE) -> 75 | F51: 5 | G51: 1 | H51: 0 | I51: 0 | J51: 0 | K51: =$L51+1 -> 8.2 | L51: =INT((10 - ((F51*32/E51) + (G51 * 0.3) + (H51 / 8) + (I51 * 0.7) + (J51 * 4)) - 0.3) * 10) * 0.1 -> 7.2
A52: 50050 | B52: =VLOOKUP($A52,Table_Data_Map!$A:$F,2,FALSE) -> 시험 3 | C52: =VLOOKUP($A52,Table_Data_Map!$A:$F,6,FALSE) -> 1 | D52: =VLOOKUP($C52,표준캐릭터설정!$A:$E,4,FALSE) -> 7.8125 | E52: =VLOOKUP($C52,표준캐릭터설정!$A:$E,5,FALSE) -> 75 | F52: 5 | G52: 1 | H52: 0 | I52: 0 | J52: 0 | K52: =$L52+1 -> 8.2 | L52: =INT((10 - ((F52*32/E52) + (G52 * 0.3) + (H52 / 8) + (I52 * 0.7) + (J52 * 4)) - 0.3) * 10) * 0.1 -> 7.2
A53: 50051 | B53: =VLOOKUP($A53,Table_Data_Map!$A:$F,2,FALSE) -> 시험 3 | C53: =VLOOKUP($A53,Table_Data_Map!$A:$F,6,FALSE) -> 1 | D53: =VLOOKUP($C53,표준캐릭터설정!$A:$E,4,FALSE) -> 7.8125 | E53: =VLOOKUP($C53,표준캐릭터설정!$A:$E,5,FALSE) -> 75 | F53: 5 | G53: 1 | H53: 0 | I53: 0 | J53: 0 | K53: =$L53+1 -> 8.2 | L53: =INT((10 - ((F53*32/E53) + (G53 * 0.3) + (H53 / 8) + (I53 * 0.7) + (J53 * 4)) - 0.3) * 10) * 0.1 -> 7.2
A54: 50052 | B54: =VLOOKUP($A54,Table_Data_Map!$A:$F,2,FALSE) -> 개발자와 대화 4 | C54: =VLOOKUP($A54,Table_Data_Map!$A:$F,6,FALSE) -> 1 | D54: =VLOOKUP($C54,표준캐릭터설정!$A:$E,4,FALSE) -> 7.8125 | E54: =VLOOKUP($C54,표준캐릭터설정!$A:$E,5,FALSE) -> 75 | F54: 5 | G54: 3 | H54: 5 | I54: 0 | J54: 0 | K54: =$L54+1 -> 7 | L54: =INT((10 - ((F54*32/E54) + (G54 * 0.3) + (H54 / 8) + (I54 * 0.7) + (J54 * 4)) - 0.3) * 10) * 0.1 -> 6
... A60: 50058 | B60: =VLOOKUP($A60,Table_Data_Map!$A:$F,2,FALSE) -> 숨겨진 방으로 | C60: =VLOOKUP($A60,Table_Data_Map!$A:$F,6,FALSE) -> 4 | D60: =VLOOKUP($C60,표준캐릭터설정!$A:$E,4,FALSE) -> 56.433409 | E60: =VLOOKUP($C60,표준캐릭터설정!$A:$E,5,FALSE) -> 99 | F60: 7 | G60: 0 | H60: 0 | I60: 1 | J60: 0 | K60: =$L60+1 -> 7.7 | L60: =INT((10 - ((F60*32/E60) + (G60 * 0.3) + (H60 / 8) + (I60 * 0.7) + (J60 * 4)) - 0.3) * 10) * 0.1 -> 6.7
...

Sheet 표준캐릭터설정
A1: 등급 | B1: 공격력 | C1: 공격속도 | D1: DPS | E1: 이동속도 | F1: 캐릭터 | L1: 무기 | S1: 갑옷 | Z1: 신발 | AG1: 장신구
F2: 이름 | G2: 힘 | H2: 민첩 | I2: 지력 | J2: 체력 | K2: 행운 | L2: 이름 | M2: SATK | N2: LATK | O2: DEF | P2: ASPD | Q2: SPD | R2: HP | S2: 이름 | T2: SATK | U2: LATK | V2: DEF | W2: ASPD | X2: SPD | Y2: HP | Z2: 이름 | AA2: SATK | AB2: LATK | AC2: DEF | AD2: ASPD | AE2: SPD | AF2: HP | AG2: 이름 | AH2: SATK | AI2: LATK | AJ2: DEF | AK2: ASPD | AL2: SPD | AM2: HP
A3: 1 | B3: =SUM($M3,$T3,$AA3,$AH3)*(INT(($G3-9)/3)+1) -> 8 | C3: =$P3*(100-$H3)*0.01-($W3+$AD3+$AK3) -> 1024 | D3: =$B3*1000/$C3 -> 7.8125 | E3: =설정!$B$1+H3+Q3+X3+AE3+AL3 -> 75 | F3: 카인 | G3: =VLOOKUP($F3,Table_Data_Character!$B:$K,6,FALSE) -> 13 | H3: =VLOOKUP($F3,Table_Data_Character!$B:$K,7,FALSE) -> 13 | I3: =VLOOKUP($F3,Table_Data_Character!$B:$K,8,FALSE) -> 13 | J3: =VLOOKUP($F3,Table_Data_Character!$B:$K,9,FALSE) -> 13 | K3: =VLOOKUP($F3,Table_Data_Character!$B:$K,10,FALSE) -> 3 | L3: 장검 | M3: =VLOOKUP($L3,Table_Data_Item!$B:$N,8,FALSE) -> 4 | N3: =VLOOKUP($L3,Table_Data_Item!$B:$N,9,FALSE) -> 2 | O3: =VLOOKUP($L3,Table_Data_Item!$B:$N,10,FALSE) -> 0 | P3: =VLOOKUP($L3,Table_Data_Item!$B:$N,11,FALSE) -> 1200 | Q3: =VLOOKUP($L3,Table_Data_Item!$B:$N,12,FALSE) -> 0 | R3: =VLOOKUP($L3,Table_Data_Item!$B:$N,13,FALSE) -> 0 | S3: 강화 가죽 갑옷 | T3: =VLOOKUP($S3,Table_Data_Item!$B:$N,8,FALSE) -> 0 | U3: =VLOOKUP($S3,Table_Data_Item!$B:$N,9,FALSE) -> 0 | V3: =VLOOKUP($S3,Table_Data_Item!$B:$N,10,FALSE) -> 5 | W3: =VLOOKUP($S3,Table_Data_Item!$B:$N,11,FALSE) -> 0 | X3: =VLOOKUP($S3,Table_Data_Item!$B:$N,12,FALSE) -> 0 | Y3: =VLOOKUP($S3,Table_Data_Item!$B:$N,13,FALSE) -> 0 | Z3: 나무 장화 | AA3: =VLOOKUP($Z3,Table_Data_Item!$B:$N,8,FALSE) -> 0 | AB3: =VLOOKUP($Z3,Table_Data_Item!$B:$N,9,FALSE) -> 0 | AC3: =VLOOKUP($Z3,Table_Data_Item!$B:$N,10,FALSE) -> 1 | AD3: =VLOOKUP($Z3,Table_Data_Item!$B:$N,11,FALSE) -> 0 | AE3: =VLOOKUP($Z3,Table_Data_Item!$B:$N,12,FALSE) -> 12 | AF3: =VLOOKUP($Z3,Table_Data_Item!$B:$N,13,FALSE) -> 0 | AG3: 금 반지 | AH3: =VLOOKUP($AG3,Table_Data_Item!$B:$N,8,FALSE) -> 0 | AI3: =VLOOKUP($AG3,Table_Data_Item!$B:$N,9,FALSE) -> 0 | AJ3: =VLOOKUP($AG3,Table_Data_Item!$B:$N,10,FALSE) -> 0 | AK3: =VLOOKUP($AG3,Table_Data_Item!$B:$N,11,FALSE) -> 20 | AL3: =VLOOKUP($AG3,Table_Data_Item!$B:$N,12,FALSE) -> 0 | AM3: =VLOOKUP($AG3,Table_Data_Item!$B:$N,13,FALSE) -> 0
A4: 2 | B4: =SUM($M4,$T4,$AA4,$AH4)*(INT(($G4-9)/3)+1) -> 18 | C4: =$P4*(100-$H4)*0.01-($W4+$AD4+$AK4) -> 978 | D4: =$B4*1000/$C4 -> 18.404908 | E4: =설정!$B$1+H4+Q4+X4+AE4+AL4 -> 83 | F4: 유고 | G4: =VLOOKUP($F4,Table_Data_Character!$B:$K,6,FALSE) -> 16 | H4: =VLOOKUP($F4,Table_Data_Character!$B:$K,7,FALSE) -> 16 | I4: =VLOOKUP($F4,Table_Data_Character!$B:$K,8,FALSE) -> 16 | J4: =VLOOKUP($F4,Table_Data_Character!$B:$K,9,FALSE) -> 16 | K4: =VLOOKUP($F4,Table_Data_Character!$B:$K,10,FALSE) -> 6 | L4: 용병 검 | M4: =VLOOKUP($L4,Table_Data_Item!$B:$N,8,FALSE) -> 6 | N4: =VLOOKUP($L4,Table_Data_Item!$B:$N,9,FALSE) -> 3 | O4: =VLOOKUP($L4,Table_Data_Item!$B:$N,10,FALSE) -> 0 | P4: =VLOOKUP($L4,Table_Data_Item!$B:$N,11,FALSE) -> 1200 | Q4: =VLOOKUP($L4,Table_Data_Item!$B:$N,12,FALSE) -> 0 | R4: =VLOOKUP($L4,Table_Data_Item!$B:$N,13,FALSE) -> 0 | S4: 강화 구리 갑옷 | T4: =VLOOKUP($S4,Table_Data_Item!$B:$N,8,FALSE) -> 0 | U4: =VLOOKUP($S4,Table_Data_Item!$B:$N,9,FALSE) -> 0 | V4: =VLOOKUP($S4,Table_Data_Item!$B:$N,10,FALSE) -> 9 | W4: =VLOOKUP($S4,Table_Data_Item!$B:$N,11,FALSE) -> 0 | X4: =VLOOKUP($S4,Table_Data_Item!$B:$N,12,FALSE) -> 0 | Y4: =VLOOKUP($S4,Table_Data_Item!$B:$N,13,FALSE) -> 0 | Z4: 가죽 장화 | AA4: =VLOOKUP($Z4,Table_Data_Item!$B:$N,8,FALSE) -> 0 | AB4: =VLOOKUP($Z4,Table_Data_Item!$B:$N,9,FALSE) -> 0 | AC4: =VLOOKUP($Z4,Table_Data_Item!$B:$N,10,FALSE) -> 3 | AD4: =VLOOKUP($Z4,Table_Data_Item!$B:$N,11,FALSE) -> 0 | AE4: =VLOOKUP($Z4,Table_Data_Item!$B:$N,12,FALSE) -> 17 | AF4: =VLOOKUP($Z4,Table_Data_Item!$B:$N,13,FALSE) -> 0 | AG4: 순금 반지 | AH4: =VLOOKUP($AG4,Table_Data_Item!$B:$N,8,FALSE) -> 0 | AI4: =VLOOKUP($AG4,Table_Data_Item!$B:$N,9,FALSE) -> 0 | AJ4: =VLOOKUP($AG4,Table_Data_Item!$B:$N,10,FALSE) -> 0 | AK4: =VLOOKUP($AG4,Table_Data_Item!$B:$N,11,FALSE) -> 30 | AL4: =VLOOKUP($AG4,Table_Data_Item!$B:$N,12,FALSE) -> 0 | AM4: =VLOOKUP($AG4,Table_Data_Item!$B:$N,13,FALSE) -> 0
A5: 3 | B5: =SUM($M5,$T5,$AA5,$AH5)*(INT(($G5-9)/3)+1) -> 32 | C5: =$P5*(100-$H5)*0.01-($W5+$AD5+$AK5) -> 932 | D5: =$B5*1000/$C5 -> 34.334764 | E5: =설정!$B$1+H5+Q5+X5+AE5+AL5 -> 91 | F5: 메이슨 | G5: =VLOOKUP($F5,Table_Data_Character!$B:$K,6,FALSE) -> 19 | H5: =VLOOKUP($F5,Table_Data_Character!$B:$K,7,FALSE) -> 19 | I5: =VLOOKUP($F5,Table_Data_Character!$B:$K,8,FALSE) -> 19 | J5: =VLOOKUP($F5,Table_Data_Character!$B:$K,9,FALSE) -> 19 | K5: =VLOOKUP($F5,Table_Data_Character!$B:$K,10,FALSE) -> 9 | L5: 기사 검 | M5: =VLOOKUP($L5,Table_Data_Item!$B:$N,8,FALSE) -> 8 | N5: =VLOOKUP($L5,Table_Data_Item!$B:$N,9,FALSE) -> 5 | O5: =VLOOKUP($L5,Table_Data_Item!$B:$N,10,FALSE) -> 0 | P5: =VLOOKUP($L5,Table_Data_Item!$B:$N,11,FALSE) -> 1200 | Q5: =VLOOKUP($L5,Table_Data_Item!$B:$N,12,FALSE) -> 0 | R5: =VLOOKUP($L5,Table_Data_Item!$B:$N,13,FALSE) -> 0 | S5: 강화 황동 갑옷 | T5: =VLOOKUP($S5,Table_Data_Item!$B:$N,8,FALSE) -> 0 | U5: =VLOOKUP($S5,Table_Data_Item!$B:$N,9,FALSE) -> 0 | V5: =VLOOKUP($S5,Table_Data_Item!$B:$N,10,FALSE) -> 13 | W5: =VLOOKUP($S5,Table_Data_Item!$B:$N,11,FALSE) -> 0 | X5: =VLOOKUP($S5,Table_Data_Item!$B:$N,12,FALSE) -> 0 | Y5: =VLOOKUP($S5,Table_Data_Item!$B:$N,13,FALSE) -> 0 | Z5: 황동 장화 | AA5: =VLOOKUP($Z5,Table_Data_Item!$B:$N,8,FALSE) -> 0 | AB5: =VLOOKUP($Z5,Table_Data_Item!$B:$N,9,FALSE) -> 0 | AC5: =VLOOKUP($Z5,Table_Data_Item!$B:$N,10,FALSE) -> 5 | AD5: =VLOOKUP($Z5,Table_Data_Item!$B:$N,11,FALSE) -> 0 | AE5: =VLOOKUP($Z5,Table_Data_Item!$B:$N,12,FALSE) -> 22 | AF5: =VLOOKUP($Z5,Table_Data_Item!$B:$N,13,FALSE) -> 0 | AG5: 루비 반지 | AH5: =VLOOKUP($AG5,Table_Data_Item!$B:$N,8,FALSE) -> 0 | AI5: =VLOOKUP($AG5,Table_Data_Item!$B:$N,9,FALSE) -> 0 | AJ5: =VLOOKUP($AG5,Table_Data_Item!$B:$N,10,FALSE) -> 0 | AK5: =VLOOKUP($AG5,Table_Data_Item!$B:$N,11,FALSE) -> 40 | AL5: =VLOOKUP($AG5,Table_Data_Item!$B:$N,12,FALSE) -> 0 | AM5: =VLOOKUP($AG5,Table_Data_Item!$B:$N,13,FALSE) -> 0
A6: 4 | B6: =SUM($M6,$T6,$AA6,$AH6)*(INT(($G6-9)/3)+1) -> 50 | C6: =$P6*(100-$H6)*0.01-($W6+$AD6+$AK6) -> 886 | D6: =$B6*1000/$C6 -> 56.433409 | E6: =설정!$B$1+H6+Q6+X6+AE6+AL6 -> 99 | F6: 패트릭 | G6: =VLOOKUP($F6,Table_Data_Character!$B:$K,6,FALSE) -> 22 | H6: =VLOOKUP($F6,Table_Data_Character!$B:$K,7,FALSE) -> 22 | I6: =VLOOKUP($F6,Table_Data_Character!$B:$K,8,FALSE) -> 22 | J6: =VLOOKUP($F6,Table_Data_Character!$B:$K,9,FALSE) -> 22 | K6: =VLOOKUP($F6,Table_Data_Character!$B:$K,10,FALSE) -> 12 | L6: 제국 검 | M6: =VLOOKUP($L6,Table_Data_Item!$B:$N,8,FALSE) -> 10 | N6: =VLOOKUP($L6,Table_Data_Item!$B:$N,9,FALSE) -> 6 | O6: =VLOOKUP($L6,Table_Data_Item!$B:$N,10,FALSE) -> 0 | P6: =VLOOKUP($L6,Table_Data_Item!$B:$N,11,FALSE) -> 1200 | Q6: =VLOOKUP($L6,Table_Data_Item!$B:$N,12,FALSE) -> 0 | R6: =VLOOKUP($L6,Table_Data_Item!$B:$N,13,FALSE) -> 0 | S6: 강화 철 갑옷 | T6: =VLOOKUP($S6,Table_Data_Item!$B:$N,8,FALSE) -> 0 | U6: =VLOOKUP($S6,Table_Data_Item!$B:$N,9,FALSE) -> 0 | V6: =VLOOKUP($S6,Table_Data_Item!$B:$N,10,FALSE) -> 17 | W6: =VLOOKUP($S6,Table_Data_Item!$B:$N,11,FALSE) -> 0 | X6: =VLOOKUP($S6,Table_Data_Item!$B:$N,12,FALSE) -> 0 | Y6: =VLOOKUP($S6,Table_Data_Item!$B:$N,13,FALSE) -> 0 | Z6: 철 장화 | AA6: =VLOOKUP($Z6,Table_Data_Item!$B:$N,8,FALSE) -> 0 | AB6: =VLOOKUP($Z6,Table_Data_Item!$B:$N,9,FALSE) -> 0 | AC6: =VLOOKUP($Z6,Table_Data_Item!$B:$N,10,FALSE) -> 7 | AD6: =VLOOKUP($Z6,Table_Data_Item!$B:$N,11,FALSE) -> 0 | AE6: =VLOOKUP($Z6,Table_Data_Item!$B:$N,12,FALSE) -> 27 | AF6: =VLOOKUP($Z6,Table_Data_Item!$B:$N,13,FALSE) -> 0 | AG6: 혈석 반지 | AH6: =VLOOKUP($AG6,Table_Data_Item!$B:$N,8,FALSE) -> 0 | AI6: =VLOOKUP($AG6,Table_Data_Item!$B:$N,9,FALSE) -> 0 | AJ6: =VLOOKUP($AG6,Table_Data_Item!$B:$N,10,FALSE) -> 0 | AK6: =VLOOKUP($AG6,Table_Data_Item!$B:$N,11,FALSE) -> 50 | AL6: =VLOOKUP($AG6,Table_Data_Item!$B:$N,12,FALSE) -> 0 | AM6: =VLOOKUP($AG6,Table_Data_Item!$B:$N,13,FALSE) -> 0
A7: 99 | B7: =SUM($M7,$T7,$AA7,$AH7)*(INT(($G7-9)/3)+1) -> 4 | C7: =$P7*(100-$H7)*0.01-($W7+$AD7+$AK7) -> 1034 | D7: =$B7*1000/$C7 -> 3.868472 | E7: =설정!$B$1+H7+Q7+X7+AE7+AL7 -> 68 | F7: 기본 캐릭터 남 | G7: =VLOOKUP($F7,Table_Data_Character!$B:$K,6,FALSE) -> 13 | H7: =VLOOKUP($F7,Table_Data_Character!$B:$K,7,FALSE) -> 13 | I7: =VLOOKUP($F7,Table_Data_Character!$B:$K,8,FALSE) -> 13 | J7: =VLOOKUP($F7,Table_Data_Character!$B:$K,9,FALSE) -> 13 | K7: =VLOOKUP($F7,Table_Data_Character!$B:$K,10,FALSE) -> 3 | L7: 나무 막대기 | M7: =VLOOKUP($L7,Table_Data_Item!$B:$N,8,FALSE) -> 2 | N7: =VLOOKUP($L7,Table_Data_Item!$B:$N,9,FALSE) -> 2 | O7: =VLOOKUP($L7,Table_Data_Item!$B:$N,10,FALSE) -> 0 | P7: =VLOOKUP($L7,Table_Data_Item!$B:$N,11,FALSE) -> 1200 | Q7: =VLOOKUP($L7,Table_Data_Item!$B:$N,12,FALSE) -> 0 | R7: =VLOOKUP($L7,Table_Data_Item!$B:$N,13,FALSE) -> 0 | S7: 낡은 옷 | T7: =VLOOKUP($S7,Table_Data_Item!$B:$N,8,FALSE) -> 0 | U7: =VLOOKUP($S7,Table_Data_Item!$B:$N,9,FALSE) -> 0 | V7: =VLOOKUP($S7,Table_Data_Item!$B:$N,10,FALSE) -> 2 | W7: =VLOOKUP($S7,Table_Data_Item!$B:$N,11,FALSE) -> 0 | X7: =VLOOKUP($S7,Table_Data_Item!$B:$N,12,FALSE) -> 0 | Y7: =VLOOKUP($S7,Table_Data_Item!$B:$N,13,FALSE) -> 0 | Z7: 낡은 신발 | AA7: =VLOOKUP($Z7,Table_Data_Item!$B:$N,8,FALSE) -> 0 | AB7: =VLOOKUP($Z7,Table_Data_Item!$B:$N,9,FALSE) -> 0 | AC7: =VLOOKUP($Z7,Table_Data_Item!$B:$N,10,FALSE) -> 1 | AD7: =VLOOKUP($Z7,Table_Data_Item!$B:$N,11,FALSE) -> 0 | AE7: =VLOOKUP($Z7,Table_Data_Item!$B:$N,12,FALSE) -> 5 | AF7: =VLOOKUP($Z7,Table_Data_Item!$B:$N,13,FALSE) -> 0 | AG7: 구리 반지 | AH7: =VLOOKUP($AG7,Table_Data_Item!$B:$N,8,FALSE) -> 0 | AI7: =VLOOKUP($AG7,Table_Data_Item!$B:$N,9,FALSE) -> 0 | AJ7: =VLOOKUP($AG7,Table_Data_Item!$B:$N,10,FALSE) -> 0 | AK7: =VLOOKUP($AG7,Table_Data_Item!$B:$N,11,FALSE) -> 10 | AL7: =VLOOKUP($AG7,Table_Data_Item!$B:$N,12,FALSE) -> 0 | AM7: =VLOOKUP($AG7,Table_Data_Item!$B:$N,13,FALSE) -> 0

Sheet 설정
A1: 기본이동속도 | B1: 50

Sheet Table_Data_Character
A1: Id | B1: dev_name | C1: Name | D1: STR | E1: DESC | F1: Grade | G1: POW | H1: DEX | I1: INT | J1: CON | K1: LUC | L1: RND_POW | M1: RND_DEX | N1: RND_INT | O1: RND_CON | P1: RND_LUC | Q1: Option_1 | R1: Option_2 | S1: Option_3 | T1: Option_4 | U1: Option_5 | V1: Option_6 | W1: Model | X1: Icon
A2: 10000 | B2: 기본 캐릭터 남 | C2: cha_n_0001 | D2: STR_CHA_N_0001 | E2: STR_CHA_N_0001_DESC | F2: 1 | G2: 13 | H2: 13 | I2: 13 | J2: 13 | K2: 3 | L2: 0 | M2: 0 | N2: 0 | O2: 0 | P2: 0 | W2: cha_0004 | X2: icon_item_6004
A3: 10001 | B3: 기본 캐릭터 여 | C3: cha_n_0002 | D3: STR_CHA_N_0002 | E3: STR_CHA_N_0002_DESC | F3: 1 | G3: 13 | H3: 13 | I3: 13 | J3: 13 | K3: 3 | L3: 0 | M3: 0 | N3: 0 | O3: 0 | P3: 0 | W3: cha_0003 | X3: icon_item_6003
A4: 10002 | B4: 카인 | C4: cha_d_0001 | D4: STR_CHA_D_0001 | E4: STR_CHA_D_0001_DESC | F4: 1 | G4: 13 | H4: 13 | I4: 13 | J4: 13 | K4: 3 | L4: 2 | M4: 2 | N4: 2 | O4: 2 | P4: 2 | W4: cha_0020 | X4: icon_item_6020
A5: 10003 | B5: 아돌 | C5: cha_d_0002 | D5: STR_CHA_D_0002 | E5: STR_CHA_D_0002_DESC | F5: 1 | G5: 18 | H5: 8 | I5: 10 | J5: 16 | K5: 3 | L5: 2 | M5: 2 | N5: 2 | O5: 2 | P5: 2 | W5: cha_0021 | X5: icon_item_6021
A6: 10004 | B6: 샤나 | C6: cha_d_0003 | D6: STR_CHA_D_0003 | E6: STR_CHA_D_0003_DESC | F6: 1 | G6: 8 | H6: 18 | I6: 16 | J6: 10 | K6: 3 | L6: 2 | M6: 2 | N6: 2 | O6: 2 | P6: 2 | W6: cha_0017 | X6: icon_item_6017
A7: 10005 | B7: 스메라기 | C7: cha_d_0004 | D7: STR_CHA_D_0004 | E7: STR_CHA_D_0004_DESC | F7: 1 | G7: 10 | H7: 16 | I7: 18 | J7: 8 | K7: 3 | L7: 2 | M7: 2 | N7: 2 | O7: 2 | P7: 2 | W7: cha_0012 | X7: icon_item_6012
A8: 10006 | B8: 아스란 | C8: cha_d_0005 | D8: STR_CHA_D_0005 | E8: STR_CHA_D_0005_DESC | F8: 1 | G8: 16 | H8: 10 | I8: 8 | J8: 18 | K8: 3 | L8: 2 | M8: 2 | N8: 2 | O8: 2 | P8: 2 | W8: cha_0001 | X8: icon_item_6001
A9: 10007 | B9: 유고 | C9: cha_c_0001 | D9: STR_CHA_C_0001 | E9: STR_CHA_C_0001_DESC | F9: 2 | G9: 16 | H9: 16 | I9: 16 | J9: 16 | K9: 6 | L9: 2 | M9: 2 | N9: 2 | O9: 2 | P9: 2 | Q9: option_satk_01 | R9: option_latk_01 | S9: option_def_01 | T9: option_aspd_01 | U9: option_spd_01 | V9: option_hp_01 | W9: cha_0019 | X9: icon_item_6019
A10: 10008 | B10: 미하엘 | C10: cha_c_0002 | D10: STR_CHA_C_0002 | E10: STR_CHA_C_0002_DESC | F10: 2 | G10: 20 | H10: 12 | I10: 14 | J10: 18 | K10: 6 | L10: 2 | M10: 2 | N10: 2 | O10: 2 | P10: 2 | Q10: option_satk_01 | R10: option_latk_01 | S10: option_def_01 | T10: option_aspd_01 | U10: option_spd_01 | V10: option_hp_01 | W10: cha_0016 | X10: icon_item_6016
A11: 10009 | B11: 다임 | C11: cha_c_0003 | D11: STR_CHA_C_0003 | E11: STR_CHA_C_0003_DESC | F11: 2 | G11: 12 | H11: 20 | I11: 18 | J11: 14 | K11: 6 | L11: 2 | M11: 2 | N11: 2 | O11: 2 | P11: 2 | Q11: option_satk_01 | R11: option_latk_01 | S11: option_def_01 | T11: option_aspd_01 | U11: option_spd_01 | V11: option_hp_01 | W11: cha_0006 | X11: icon_item_6006
A12: 10010 | B12: 후미코 | C12: cha_c_0004 | D12: STR_CHA_C_0004 | E12: STR_CHA_C_0004_DESC | F12: 2 | G12: 14 | H12: 18 | I12: 20 | J12: 12 | K12: 6 | L12: 2 | M12: 2 | N12: 2 | O12: 2 | P12: 2 | Q12: option_satk_01 | R12: option_latk_01 | S12: option_def_01 | T12: option_aspd_01 | U12: option_spd_01 | V12: option_hp_01 | W12: cha_0010 | X12: icon_item_6010
A13: 10011 | B13: 키라 | C13: cha_c_0005 | D13: STR_CHA_C_0005 | E13: STR_CHA_C_0005_DESC | F13: 2 | G13: 18 | H13: 14 | I13: 12 | J13: 20 | K13: 6 | L13: 2 | M13: 2 | N13: 2 | O13: 2 | P13: 2 | Q13: option_satk_01 | R13: option_latk_01 | S13: option_def_01 | T13: option_aspd_01 | U13: option_spd_01 | V13: option_hp_01 | W13: cha_0023 | X13: icon_item_6023
A14: 10012 | B14: 메이슨 | C14: cha_b_0001 | D14: STR_CHA_B_0001 | E14: STR_CHA_B_0001_DESC | F14: 3 | G14: 19 | H14: 19 | I14: 19 | J14: 19 | K14: 9 | L14: 2 | M14: 2 | N14: 2 | O14: 2 | P14: 2 | Q14: option_satk_02 | R14: option_latk_02 | S14: option_def_02 | T14: option_aspd_02 | U14: option_spd_02 | V14: option_hp_02 | W14: cha_0014 | X14: icon_item_6014
A15: 10013 | B15: 발자르 | C15: cha_b_0002 | D15: STR_CHA_B_0002 | E15: STR_CHA_B_0002_DESC | F15: 3 | G15: 22 | H15: 16 | I15: 18 | J15: 20 | K15: 9 | L15: 2 | M15: 2 | N15: 2 | O15: 2 | P15: 2 | Q15: option_satk_02 | R15: option_latk_02 | S15: option_def_02 | T15: option_aspd_02 | U15: option_spd_02 | V15: option_hp_02 | W15: cha_0008 | X15: icon_item_6008
A16: 10014 | B16: 세실 | C16: cha_b_0003 | D16: STR_CHA_B_0003 | E16: STR_CHA_B_0003_DESC | F16: 3 | G16: 16 | H16: 22 | I16: 20 | J16: 18 | K16: 9 | L16: 2 | M16: 2 | N16: 2 | O16: 2 | P16: 2 | Q16: option_satk_02 | R16: option_latk_02 | S16: option_def_02 | T16: option_aspd_02 | U16: option_spd_02 | V16: option_hp_02 | W16: cha_0015 | X16: icon_item_6015
A17: 10015 | B17: 에밀리오 | C17: cha_b_0004 | D17: STR_CHA_B_0004 | E17: STR_CHA_B_0004_DESC | F17: 3 | G17: 18 | H17: 20 | I17: 22 | J17: 16 | K17: 9 | L17: 2 | M17: 2 | N17: 2 | O17: 2 | P17: 2 | Q17: option_satk_02 | R17: option_latk_02 | S17: option_def_02 | T17: option_aspd_02 | U17: option_spd_02 | V17: option_hp_02 | W17: cha_0009 | X17: icon_item_6009
A18: 10016 | B18: 조슈아 | C18: cha_b_0005 | D18: STR_CHA_B_0005 | E18: STR_CHA_B_0005_DESC | F18: 3 | G18: 20 | H18: 18 | I18: 16 | J18: 22 | K18: 9 | L18: 2 | M18: 2 | N18: 2 | O18: 2 | P18: 2 | Q18: option_satk_02 | R18: option_latk_02 | S18: option_def_02 | T18: option_aspd_02 | U18: option_spd_02 | V18: option_hp_02 | W18: cha_0018 | X18: icon_item_6018
A19: 10017 | B19: 패트릭 | C19: cha_a_0001 | D19: STR_CHA_A_0001 | E19: STR_CHA_A_0001_DESC | F19: 4 | G19: 22 | H19: 22 | I19: 22 | J19: 22 | K19: 12 | L19: 2 | M19: 2 | N19: 2 | O19: 2 | P19: 2 | Q19: option_satk_03 | R19: option_latk_03 | S19: option_def_03 | T19: option_aspd_03 | U19: option_spd_03 | V19: option_hp_03 | W19: cha_0011 | X19: icon_item_6011
A20: 10018 | B20: 앤드류 | C20: cha_a_0002 | D20: STR_CHA_A_0002 | E20: STR_CHA_A_0002_DESC | F20: 4 | G20: 25 | H20: 19 | I20: 21 | J20: 23 | K20: 12 | L20: 2 | M20: 2 | N20: 2 | O20: 2 | P20: 2 | Q20: option_satk_03 | R20: option_latk_03 | S20: option_def_03 | T20: option_aspd_03 | U20: option_spd_03 | V20: option_hp_03 | W20: cha_0007 | X20: icon_item_6007
... A23: 10021 | B23: 카네키 | C23: cha_a_0005 | D23: STR_CHA_A_0005 | E23: STR_CHA_A_0005_DESC | F23: 4 | G23: 23 | H23: 21 | I23: 19 | J23: 25 | K23: 12 | L23: 2 | M23: 2 | N23: 2 | O23: 2 | P23: 2 | Q23: option_satk_03 | R23: option_latk_03 | S23: option_def_03 | T23: option_aspd_03 | U23: option_spd_03 | V23: option_hp_03 | W23: cha_0002 | X23: icon_item_6002

Sheet Table_Data_Item
A1: Id | B1: dev_name | C1: Name | D1: STR | E1: DESC | F1: Grade | G1: Type | H1: Slot_Idx | I1: SATK | J1: LATK | K1: DEF | L1: ASPD | M1: SPD | N1: HP | O1: Effect | P1: Effect_Value | Q1: Option_1 | R1: Option_2 | S1: Option_3 | T1: Option_4 | U1: Option_5 | V1: Is_Stack | W1: Price | X1: Coin_Price | Y1: Key | Z1: Key_Amount | AA1: Icon | AB1: Drop_1 | AC1: Drop_2 | AD1: Drop_3
A2: 30000 | B2: 빨간 물약 | C2: item_potion_heal_01 | D2: STR_ITEM_POTION_HEAL_01 | E2: STR_ITEM_POTION_HEAL_01_DESC | F2: 0 | G2: Potion | H2: 0 | I2: 0 | J2: 0 | K2: 0 | L2: 0 | M2: 0 | N2: 0 | O2: ADD_HP | P2: 20 | V2: TRUE | W2: 200 | X2: 0 | Z2: 0 | AA2: icon_item_0001
A3: 30001 | B3: 주황 물약 | C3: item_potion_heal_02 | D3: STR_ITEM_POTION_HEAL_02 | E3: STR_ITEM_POTION_HEAL_02_DESC | F3: 0 | G3: Potion | H3: 0 | I3: 0 | J3: 0 | K3: 0 | L3: 0 | M3: 0 | N3: 0 | O3: ADD_HP | P3: 60 | V3: TRUE | W3: 600 | X3: 0 | Z3: 0 | AA3: icon_item_0002
A4: 30002 | B4: 보라 물약 | C4: item_potion_heal_03 | D4: STR_ITEM_POTION_HEAL_03 | E4: STR_ITEM_POTION_HEAL_03_DESC | F4: 0 | G4: Potion | H4: 0 | I4: 0 | J4: 0 | K4: 0 | L4: 0 | M4: 0 | N4: 0 | O4: ADD_HP | P4: 100 | V4: TRUE | W4: 1000 | X4: 0 | Z4: 0 | AA4: icon_item_0003
A5: 30003 | B5: 노랑 물약 | C5: item_potion_heal_04 | D5: STR_ITEM_POTION_HEAL_04 | E5: STR_ITEM_POTION_HEAL_04_DESC | F5: 0 | G5: Potion | H5: 0 | I5: 0 | J5: 0 | K5: 0 | L5: 0 | M5: 0 | N5: 0 | O5: ADD_HP | P5: 150 | V5: TRUE | W5: 1500 | X5: 0 | Z5: 0 | AA5: icon_item_0004
A6: 30004 | B6: 하얀 물약 | C6: item_potion_heal_05 | D6: STR_ITEM_POTION_HEAL_05 | E6: STR_ITEM_POTION_HEAL_05_DESC | F6: 0 | G6: Potion | H6: 0 | I6: 0 | J6: 0 | K6: 0 | L6: 0 | M6: 0 | N6: 0 | O6: ADD_HP | P6: 200 | V6: TRUE | W6: 2000 | X6: 0 | Z6: 0 | AA6: icon_item_0005
A7: 31000 | B7: 낡은 옷 | C7: item_equip_n_ar_01 | D7: STR_ITEM_EQUIP_N_AR_01 | E7: STR_ITEM_EQUIP_N_AR_01_DESC | F7: 1 | G7: Equip | H7: 2 | I7: 0 | J7: 0 | K7: 2 | L7: 0 | M7: 0 | N7: 0 | O7: None | P7: 0 | V7: FALSE | W7: 10 | X7: 0 | Z7: 0 | AA7: icon_item_1000
A8: 31001 | B8: 가죽 갑옷 | C8: item_equip_n_ar_02 | D8: STR_ITEM_EQUIP_N_AR_02 | E8: STR_ITEM_EQUIP_N_AR_02_DESC | F8: 1 | G8: Equip | H8: 2 | I8: 0 | J8: 0 | K8: 4 | L8: 0 | M8: 0 | N8: 0 | O8: None | P8: 0 | V8: FALSE | W8: 5000 | X8: 0 | Z8: 0 | AA8: icon_item_1001
A9: 31002 | B9: 강화 가죽 갑옷 | C9: item_equip_n_ar_03 | D9: STR_ITEM_EQUIP_N_AR_03 | E9: STR_ITEM_EQUIP_N_AR_03_DESC | F9: 1 | G9: Equip | H9: 2 | I9: 0 | J9: 0 | K9: 5 | L9: 0 | M9: 0 | N9: 0 | O9: None | P9: 0 | V9: FALSE | W9: 7500 | X9: 0 | Z9: 0 | AA9: icon_item_1002
A10: 31003 | B10: 레어 가죽 갑옷 | C10: item_equip_n_ar_04 | D10: STR_ITEM_EQUIP_N_AR_04 | E10: STR_ITEM_EQUIP_N_AR_04_DESC | F10: 1 | G10: Equip | H10: 2 | I10: 0 | J10: 0 | K10: 5 | L10: 0 | M10: 0 | N10: 0 | O10: None | P10: 0 | Q10: option_pow_01 | R10: option_dex_01 | S10: option_int_01 | T10: option_con_01 | U10: option_luc_01 | V10: FALSE | W10: 10000 | X10: 0 | Z10: 0 | AA10: icon_item_1003
A11: 31004 | B11: 천 옷 | C11: item_equip_n_ar_05 | D11: STR_ITEM_EQUIP_N_AR_05 | E11: STR_ITEM_EQUIP_N_AR_05_DESC | F11: 1 | G11: Equip | H11: 2 | I11: 0 | J11: 0 | K11: 2 | L11: 0 | M11: 0 | N11: 20 | O11: None | P11: 0 | V11: FALSE | W11: 5000 | X11: 0 | Z11: 0 | AA11: icon_item_1201
A12: 31005 | B12: 강화 천 옷 | C12: item_equip_n_ar_06 | D12: STR_ITEM_EQUIP_N_AR_06 | E12: STR_ITEM_EQUIP_N_AR_06_DESC | F12: 1 | G12: Equip | H12: 2 | I12: 0 | J12: 0 | K12: 3 | L12: 0 | M12: 0 | N12: 30 | O12: None | P12: 0 | V12: FALSE | W12: 7500 | X12: 0 | Z12: 0 | AA12: icon_item_1202
A13: 31006 | B13: 레어 천 옷 | C13: item_equip_n_ar_07 | D13: STR_ITEM_EQUIP_N_AR_07 | E13: STR_ITEM_EQUIP_N_AR_07_DESC | F13: 1 | G13: Equip | H13: 2 | I13: 0 | J13: 0 | K13: 3 | L13: 0 | M13: 0 | N13: 30 | O13: None | P13: 0 | Q13: option_pow_01 | R13: option_dex_01 | S13: option_int_01 | T13: option_con_01 | U13: option_luc_01 | V13: FALSE | W13: 10000 | X13: 0 | Z13: 0 | AA13: icon_item_1203
A14: 31007 | B14: 구리 갑옷 | C14: item_equip_n_ar_08 | D14: STR_ITEM_EQUIP_N_AR_08 | E14: STR_ITEM_EQUIP_N_AR_08_DESC | F14: 2 | G14: Equip | H14: 2 | I14: 0 | J14: 0 | K14: 8 | L14: 0 | M14: 0 | N14: 0 | O14: None | P14: 0 | V14: FALSE | W14: 25000 | X14: 0 | Z14: 0 | AA14: icon_item_1003
A15: 31008 | B15: 강화 구리 갑옷 | C15: item_equip_n_ar_09 | D15: STR_ITEM_EQUIP_N_AR_09 | E15: STR_ITEM_EQUIP_N_AR_09_DESC | F15: 2 | G15: Equip | H15: 2 | I15: 0 | J15: 0 | K15: 9 | L15: 0 | M15: 0 | N15: 0 | O15: None | P15: 0 | V15: FALSE | W15: 37500 | X15: 0 | Z15: 0 | AA15: icon_item_1004
A16: 31009 | B16: 레어 구리 갑옷 | C16: item_equip_n_ar_10 | D16: STR_ITEM_EQUIP_N_AR_10 | E16: STR_ITEM_EQUIP_N_AR_10_DESC | F16: 2 | G16: Equip | H16: 2 | I16: 0 | J16: 0 | K16: 9 | L16: 0 | M16: 0 | N16: 0 | O16: None | P16: 0 | Q16: option_pow_01 | R16: option_dex_01 | S16: option_int_01 | T16: option_con_01 | U16: option_luc_01 | V16: FALSE | W16: 50000 | X16: 0 | Z16: 0 | AA16: icon_item_1004
A17: 31010 | B17: 가죽 옷 | C17: item_equip_n_ar_11 | D17: STR_ITEM_EQUIP_N_AR_11 | E17: STR_ITEM_EQUIP_N_AR_11_DESC | F17: 2 | G17: Equip | H17: 2 | I17: 0 | J17: 0 | K17: 4 | L17: 0 | M17: 0 | N17: 40 | O17: None | P17: 0 | V17: FALSE | W17: 25000 | X17: 0 | Z17: 0 | AA17: icon_item_1204
A18: 31011 | B18: 강화 가죽 옷 | C18: item_equip_n_ar_12 | D18: STR_ITEM_EQUIP_N_AR_12 | E18: STR_ITEM_EQUIP_N_AR_12_DESC | F18: 2 | G18: Equip | H18: 2 | I18: 0 | J18: 0 | K18: 5 | L18: 0 | M18: 0 | N18: 50 | O18: None | P18: 0 | V18: FALSE | W18: 37500 | X18: 0 | Z18: 0 | AA18: icon_item_1205
A19: 31012 | B19: 레어 가죽 옷 | C19: item_equip_n_ar_13 | D19: STR_ITEM_EQUIP_N_AR_13 | E19: STR_ITEM_EQUIP_N_AR_13_DESC | F19: 2 | G19: Equip | H19: 2 | I19: 0 | J19: 0 | K19: 5 | L19: 0 | M19: 0 | N19: 50 | O19: None | P19: 0 | Q19: option_pow_01 | R19: option_dex_01 | S19: option_int_01 | T19: option_con_01 | U19: option_luc_01 | V19: FALSE | W19: 50000 | X19: 0 | Z19: 0 | AA19: icon_item_1206
A20: 31013 | B20: 황동 갑옷 | C20: item_equip_n_ar_14 | D20: STR_ITEM_EQUIP_N_AR_14 | E20: STR_ITEM_EQUIP_N_AR_14_DESC | F20: 3 | G20: Equip | H20: 2 | I20: 0 | J20: 0 | K20: 12 | L20: 0 | M20: 0 | N20: 0 | O20: None | P20: 0 | V20: FALSE | W20: 125000 | X20: 0 | Z20: 0 | AA20: icon_item_1005
A21: 31014 | B21: 강화 황동 갑옷 | C21: item_equip_n_ar_15 | D21: STR_ITEM_EQUIP_N_AR_15 | E21: STR_ITEM_EQUIP_N_AR_15_DESC | F21: 3 | G21: Equip | H21: 2 | I21: 0 | J21: 0 | K21: 13 | L21: 0 | M21: 0 | N21: 0 | O21: None | P21: 0 | V21: FALSE | W21: 187500 | X21: 0 | Z21: 0 | AA21: icon_item_1006
A22: 31015 | B22: 레어 황동 갑옷 | C22: item_equip_n_ar_16 | D22: STR_ITEM_EQUIP_N_AR_16 | E22: STR_ITEM_EQUIP_N_AR_16_DESC | F22: 3 | G22: Equip | H22: 2 | I22: 0 | J22: 0 | K22: 13 | L22: 0 | M22: 0 | N22: 0 | O22: None | P22: 0 | Q22: option_pow_01 | R22: option_dex_01 | S22: option_int_01 | T22: option_con_01 | U22: option_luc_01 | V22: FALSE | W22: 250000 | X22: 0 | Z22: 0 | AA22: icon_item_1006
A23: 31016 | B23: 무복 | C23: item_equip_n_ar_17 | D23: STR_ITEM_EQUIP_N_AR_17 | E23: STR_ITEM_EQUIP_N_AR_17_DESC | F23: 3 | G23: Equip | H23: 2 | I23: 0 | J23: 0 | K23: 6 | L23: 0 | M23: 0 | N23: 60 | O23: None | P23: 0 | V23: FALSE | W23: 125000 | X23: 0 | Z23: 0 | AA23: icon_item_1207
A24: 31017 | B24: 장식된 무복 | C24: item_equip_n_ar_18 | D24: STR_ITEM_EQUIP_N_AR_18 | E24: STR_ITEM_EQUIP_N_AR_18_DESC | F24: 3 | G24: Equip | H24: 2 | I24: 0 | J24: 0 | K24: 7 | L24: 0 | M24: 0 | N24: 70 | O24: None | P24: 0 | V24: FALSE | W24: 187500 | X24: 0 | Z24: 0 | AA24: icon_item_1208
A25: 31018 | B25: 레어 무복 | C25: item_equip_n_ar_19 | D25: STR_ITEM_EQUIP_N_AR_19 | E25: STR_ITEM_EQUIP_N_AR_19_DESC | F25: 3 | G25: Equip | H25: 2 | I25: 0 | J25: 0 | K25: 7 | L25: 0 | M25: 0 | N25: 70 | O25: None | P25: 0 | Q25: option_pow_01 | R25: option_dex_01 | S25: option_int_01 | T25: option_con_01 | U25: option_luc_01 | V25: FALSE | W25: 250000 | X25: 0 | Z25: 0 | AA25: icon_item_1209
A26: 31019 | B26: 철 갑옷 | C26: item_equip_n_ar_20 | D26: STR_ITEM_EQUIP_N_AR_20 | E26: STR_ITEM_EQUIP_N_AR_20_DESC | F26: 4 | G26: Equip | H26: 2 | I26: 0 | J26: 0 | K26: 16 | L26: 0 | M26: 0 | N26: 0 | O26: None | P26: 0 | V26: FALSE | W26: 625000 | X26: 0 | Z26: 0 | AA26: icon_item_1005
A27: 31020 | B27: 강화 철 갑옷 | C27: item_equip_n_ar_21 | D27: STR_ITEM_EQUIP_N_AR_21 | E27: STR_ITEM_EQUIP_N_AR_21_DESC | F27: 4 | G27: Equip | H27: 2 | I27: 0 | J27: 0 | K27: 17 | L27: 0 | M27: 0 | N27: 0 | O27: None | P27: 0 | V27: FALSE | W27: 937500 | X27: 0 | Z27: 0 | AA27: icon_item_1006
A28: 31021 | B28: 레어 철 갑옷 | C28: item_equip_n_ar_22 | D28: STR_ITEM_EQUIP_N_AR_22 | E28: STR_ITEM_EQUIP_N_AR_22_DESC | F28: 4 | G28: Equip | H28: 2 | I28: 0 | J28: 0 | K28: 17 | L28: 0 | M28: 0 | N28: 0 | O28: None | P28: 0 | Q28: option_pow_01 | R28: option_dex_01 | S28: option_int_01 | T28: option_con_01 | U28: option_luc_01 | V28: FALSE | W28: 1250000 | X28: 0 | Z28: 0 | AA28: icon_item_1006
A29: 31022 | B29: 법사 옷 | C29: item_equip_n_ar_23 | D29: STR_ITEM_EQUIP_N_AR_23 | E29: STR_ITEM_EQUIP_N_AR_23_DESC | F29: 4 | G29: Equip | H29: 2 | I29: 0 | J29: 0 | K29: 8 | L29: 0 | M29: 0 | N29: 80 | O29: None | P29: 0 | V29: FALSE | W29: 625000 | X29: 0 | Z29: 0 | AA29: icon_item_1207
A30: 31023 | B30: 장식된 법사 옷 | C30: item_equip_n_ar_24 | D30: STR_ITEM_EQUIP_N_AR_24 | E30: STR_ITEM_EQUIP_N_AR_24_DESC | F30: 4 | G30: Equip | H30: 2 | I30: 0 | J30: 0 | K30: 9 | L30: 0 | M30: 0 | N30: 90 | O30: None | P30: 0 | V30: FALSE | W30: 937500 | X30: 0 | Z30: 0 | AA30: icon_item_1208
A31: 31024 | B31: 레어 법사 옷 | C31: item_equip_n_ar_25 | D31: STR_ITEM_EQUIP_N_AR_25 | E31: STR_ITEM_EQUIP_N_AR_25_DESC | F31: 4 | G31: Equip | H31: 2 | I31: 0 | J31: 0 | K31: 9 | L31: 0 | M31: 0 | N31: 90 | O31: None | P31: 0 | Q31: option_pow_01 | R31: option_dex_01 | S31: option_int_01 | T31: option_con_01 | U31: option_luc_01 | V31: FALSE | W31: 1250000 | X31: 0 | Z31: 0 | AA31: icon_item_1209
A32: 32000 | B32: 구리 반지 | C32: item_equip_n_ac_01 | D32: STR_ITEM_EQUIP_N_AC_01 | E32: STR_ITEM_EQUIP_N_AC_01_DESC | F32: 1 | G32: Equip | H32: 0 | I32: 0 | J32: 0 | K32: 0 | L32: 10 | M32: 0 | N32: 0 | O32: None | P32: 0 | V32: FALSE | W32: 10 | X32: 0 | Z32: 0 | AA32: icon_item_2000
A33: 32001 | B33: 은 반지 | C33: item_equip_n_ac_02 | D33: STR_ITEM_EQUIP_N_AC_02 | E33: STR_ITEM_EQUIP_N_AC_02_DESC | F33: 1 | G33: Equip | H33: 0 | I33: 0 | J33: 0 | K33: 0 | L33: 15 | M33: 0 | N33: 0 | O33: None | P33: 0 | V33: FALSE | W33: 6250 | X33: 0 | Z33: 0 | AA33: icon_item_2001
A34: 32002 | B34: 금 반지 | C34: item_equip_n_ac_03 | D34: STR_ITEM_EQUIP_N_AC_03 | E34: STR_ITEM_EQUIP_N_AC_03_DESC | F34: 1 | G34: Equip | H34: 0 | I34: 0 | J34: 0 | K34: 0 | L34: 20 | M34: 0 | N34: 0 | O34: None | P34: 0 | V34: FALSE | W34: 9370 | X34: 0 | Z34: 0 | AA34: icon_item_2002
A35: 32003 | B35: 마법사의 반지 | C35: item_equip_n_ac_04 | D35: STR_ITEM_EQUIP_N_AC_04 | E35: STR_ITEM_EQUIP_N_AC_04_DESC | F35: 1 | G35: Equip | H35: 0 | I35: 0 | J35: 0 | K35: 0 | L35: 22 | M35: 0 | N35: 0 | O35: None | P35: 0 | Q35: option_pow_01 | R35: option_dex_01 | S35: option_int_01 | T35: option_con_01 | U35: option_luc_01 | V35: FALSE | W35: 12500 | X35: 0 | Z35: 0 | AA35: icon_item_2003
A36: 32004 | B36: 백금 반지 | C36: item_equip_n_ac_05 | D36: STR_ITEM_EQUIP_N_AC_05 | E36: STR_ITEM_EQUIP_N_AC_05_DESC | F36: 2 | G36: Equip | H36: 0 | I36: 0 | J36: 0 | K36: 0 | L36: 25 | M36: 0 | N36: 0 | O36: None | P36: 0 | V36: FALSE | W36: 31250 | X36: 0 | Z36: 0 | AA36: icon_item_2001
A37: 32005 | B37: 순금 반지 | C37: item_equip_n_ac_06 | D37: STR_ITEM_EQUIP_N_AC_06 | E37: STR_ITEM_EQUIP_N_AC_06_DESC | F37: 2 | G37: Equip | H37: 0 | I37: 0 | J37: 0 | K37: 0 | L37: 30 | M37: 0 | N37: 0 | O37: None | P37: 0 | V37: FALSE | W37: 46850 | X37: 0 | Z37: 0 | AA37: icon_item_2002
A38: 32006 | B38: 붉은 마법 반지 | C38: item_equip_n_ac_07 | D38: STR_ITEM_EQUIP_N_AC_07 | E38: STR_ITEM_EQUIP_N_AC_07_DESC | F38: 2 | G38: Equip | H38: 0 | I38: 0 | J38: 0 | K38: 0 | L38: 32 | M38: 0 | N38: 0 | O38: None | P38: 0 | Q38: option_pow_01 | R38: option_dex_01 | S38: option_int_01 | T38: option_con_01 | U38: option_luc_01 | V38: FALSE | W38: 62500 | X38: 0 | Z38: 0 | AA38: icon_item_2003
A39: 32007 | B39: 사파이어 반지 | C39: item_equip_n_ac_08 | D39: STR_ITEM_EQUIP_N_AC_08 | E39: STR_ITEM_EQUIP_N_AC_08_DESC | F39: 3 | G39: Equip | H39: 0 | I39: 0 | J39: 0 | K39: 0 | L39: 35 | M39: 0 | N39: 0 | O39: None | P39: 0 | V39: FALSE | W39: 156250 | X39: 0 | Z39: 0 | AA39: icon_item_2001
A40: 32008 | B40: 루비 반지 | C40: item_equip_n_ac_09 | D40: STR_ITEM_EQUIP_N_AC_09 | E40: STR_ITEM_EQUIP_N_AC_09_DESC | F40: 3 | G40: Equip | H40: 0 | I40: 0 | J40: 0 | K40: 0 | L40: 40 | M40: 0 | N40: 0 | O40: None | P40: 0 | V40: FALSE | W40: 234250 | X40: 0 | Z40: 0 | AA40: icon_item_2002
...

Sheet Table_Data_Map
A1: Id | B1: dev_name | C1: Name | D1: STR | E1: DESC | F1: Region_Id | G1: Grade | H1: Type | I1: Cond_Gold | J1: Cond_Silver | K1: Price | L1: Model | M1: Image | N1: Sound | O1: Icon | P1: Need_Slot_Num | Q1: Reward_Gold | R1: Drop_1 | S1: Drop_2 | T1: Drop_3 | U1: Add_Drop_1 | V1: Add_Drop_2
A2: 50000 | B2: 튜토리얼 1 | C2: map_s1_001 | D2: STR_MAP_S1_001 | E2: STR_MAP_S1_001_DESC | F2: 1 | G2: 99 | H2: Move | I2: 8.8 | J2: 7.8 | K2: 0 | L2: pf_Map_50000 | M2: img_map_0002 | N2: bgm_11 | O2: icon_map_0002 | P2: 1 | Q2: 0 | R2: drop_0008
A3: 50001 | B3: 튜토리얼 2 | C3: map_s1_002 | D3: STR_MAP_S1_002 | E3: STR_MAP_S1_002_DESC | F3: 1 | G3: 99 | H3: Move | I3: 9.2 | J3: 8.2 | K3: 0 | L3: pf_Map_50001 | M3: img_map_0002 | N3: bgm_11 | O3: icon_map_0002 | P3: 1 | Q3: 0 | R3: drop_0008
A4: 50002 | B4: 튜토리얼 3 | C4: map_s1_003 | D4: STR_MAP_S1_003 | E4: STR_MAP_S1_003_DESC | F4: 1 | G4: 99 | H4: Move | I4: 8.8 | J4: 7.8 | K4: 0 | L4: pf_Map_50002 | M4: img_map_0002 | N4: bgm_11 | O4: icon_map_0002 | P4: 1 | Q4: 0 | R4: drop_0008
A5: 50003 | B5: 튜토리얼 4 | C5: map_s1_004 | D5: STR_MAP_S1_004 | E5: STR_MAP_S1_004_DESC | F5: 1 | G5: 99 | H5: Move | I5: 8.8 | J5: 7.8 | K5: 0 | L5: pf_Map_50003 | M5: img_map_0002 | N5: bgm_11 | O5: icon_map_0002 | P5: 1 | Q5: 0 | R5: drop_0008
A6: 50004 | B6: 숲 속 마을 입구 | C6: map_s2_001 | D6: STR_MAP_S2_001 | E6: STR_MAP_S2_001_DESC | F6: 2 | G6: 1 | H6: Move | I6: 7.2 | J6: 6.2 | K6: 0 | L6: pf_Map_50004 | M6: img_map_0001 | N6: bgm_21 | O6: icon_map_0001 | P6: 1 | Q6: 0 | R6: drop_0009 | U6: drop_0010 | V6: drop_0011
A7: 50005 | B7: 숲 속 마을 여관 | C7: map_s2_002 | D7: STR_MAP_S2_002 | E7: STR_MAP_S2_002_DESC | F7: 2 | G7: 1 | H7: Move | I7: 6.2 | J7: 5.2 | K7: 0 | L7: pf_Map_50005 | M7: img_map_0003 | N7: bgm_21 | O7: icon_map_0003 | P7: 1 | Q7: 0 | R7: drop_0009 | U7: drop_0010 | V7: drop_0011
A8: 50006 | B8: 이사벨과 대화 | C8: map_s2_003 | D8: STR_MAP_S2_003 | E8: STR_MAP_S2_003_DESC | F8: 2 | G8: 1 | H8: Talk | I8: 9.1 | J8: 8.1 | K8: 0 | L8: pf_Map_50006 | M8: img_map_0004 | N8: bgm_22 | O8: icon_map_0004 | P8: 1 | Q8: 0 | R8: drop_0009 | U8: drop_0010 | V8: drop_0011
A9: 50007 | B9: 촌장님 집으로 | C9: map_s2_004 | D9: STR_MAP_S2_004 | E9: STR_MAP_S2_004_DESC | F9: 2 | G9: 1 | H9: Move | I9: 7.4 | J9: 6.4 | K9: 0 | L9: pf_Map_50007 | M9: img_map_0003 | N9: bgm_21 | O9: icon_map_0003 | P9: 1 | Q9: 0 | R9: drop_0009 | U9: drop_0010 | V9: drop_0011
A10: 50008 | B10: 촌장님과 대화 | C10: map_s2_005 | D10: STR_MAP_S2_005 | E10: STR_MAP_S2_005_DESC | F10: 2 | G10: 1 | H10: SlowTalk | I10: 3.3 | J10: 2.3 | K10: 0 | L10: pf_Map_50008 | M10: img_map_0005 | N10: bgm_22 | O10: icon_map_0005 | P10: 3 | Q10: 0 | R10: drop_0009 | U10: drop_0010 | V10: drop_0011
A11: 50009 | B11: 숲 속 마을 북쪽으로 | C11: map_s2_006 | D11: STR_MAP_S2_006 | E11: STR_MAP_S2_006_DESC | F11: 2 | G11: 1 | H11: Move | I11: 6.1 | J11: 5.1 | K11: 0 | L11: pf_Map_50009 | M11: img_map_0005 | N11: bgm_21 | O11: icon_map_0005 | P11: 1 | Q11: 0 | R11: drop_0009 | U11: drop_0010 | V11: drop_0011
A12: 50010 | B12: 슬라임 처치 | C12: map_s2_007 | D12: STR_MAP_S2_007 | E12: STR_MAP_S2_007_DESC | F12: 2 | G12: 1 | H12: Monster | I12: 5.4 | J12: 4.4 | K12: 0 | L12: pf_Map_50010 | M12: img_map_0006 | N12: bgm_23 | O12: icon_map_0006 | P12: 3 | Q12: 0 | R12: drop_0009 | U12: drop_0010 | V12: drop_0011
A13: 50011 | B13: 훈련소로 이동 1 | C13: map_s2_008 | D13: STR_MAP_S2_008 | E13: STR_MAP_S2_008_DESC | F13: 2 | G13: 1 | H13: Move | I13: 6.6 | J13: 5.6 | K13: 0 | L13: pf_Map_50011 | M13: img_map_0003 | N13: bgm_21 | O13: icon_map_0003 | P13: 1 | Q13: 0 | R13: drop_0009 | U13: drop_0010 | V13: drop_0011
A14: 50012 | B14: 훈련소로 이동 2 | C14: map_s2_009 | D14: STR_MAP_S2_009 | E14: STR_MAP_S2_009_DESC | F14: 2 | G14: 1 | H14: Move | I14: 6.6 | J14: 5.6 | K14: 0 | L14: pf_Map_50012 | M14: img_map_0007 | N14: bgm_21 | O14: icon_map_0007 | P14: 1 | Q14: 0 | R14: drop_0009 | U14: drop_0010 | V14: drop_0011
A15: 50013 | B15: 훈련대장과 대화 | C15: map_s2_010 | D15: STR_MAP_S2_010 | E15: STR_MAP_S2_010_DESC | F15: 2 | G15: 1 | H15: Talk | I15: 8.2 | J15: 7.2 | K15: 0 | L15: pf_Map_50013 | M15: img_map_0008 | N15: bgm_22 | O15: icon_map_0008 | P15: 1 | Q15: 0 | R15: drop_0009
A16: 50014 | B16: 허수아비 처치 | C16: map_s2_011 | D16: STR_MAP_S2_011 | E16: STR_MAP_S2_011_DESC | F16: 2 | G16: 1 | H16: Monster | I16: 4.9 | J16: 3.9 | K16: 0 | L16: pf_Map_50014 | M16: img_map_0008 | N16: bgm_21 | O16: icon_map_0008 | P16: 1 | Q16: 0 | R16: drop_0009 | U16: drop_0010 | V16: drop_0011
A17: 50015 | B17: 상정가로 이동 | C17: map_s2_012 | D17: STR_MAP_S2_012 | E17: STR_MAP_S2_012_DESC | F17: 2 | G17: 1 | H17: Move | I17: 7.2 | J17: 6.2 | K17: 0 | L17: pf_Map_50015 | M17: img_map_0007 | N17: bgm_21 | O17: icon_map_0007 | P17: 1 | Q17: 0 | R17: drop_0009 | U17: drop_0010 | V17: drop_0011
A18: 50016 | B18: 물약 상인과 대화 | C18: map_s2_013 | D18: STR_MAP_S2_013 | E18: STR_MAP_S2_013_DESC | F18: 2 | G18: 1 | H18: Talk | I18: 8.3 | J18: 7.3 | K18: 0 | L18: pf_Map_50016 | M18: img_map_0009 | N18: bgm_22 | O18: icon_map_0009 | P18: 1 | Q18: 0 | R18: drop_0009
A19: 50017 | B19: 무기 상인과 대화 | C19: map_s2_014 | D19: STR_MAP_S2_014 | E19: STR_MAP_S2_014_DESC | F19: 2 | G19: 1 | H19: Talk | I19: 8.3 | J19: 7.3 | K19: 0 | L19: pf_Map_50017 | M19: img_map_0009 | N19: bgm_22 | O19: icon_map_0009 | P19: 1 | Q19: 0 | R19: drop_0009
A20: 50018 | B20: 대장장이와 대화 | C20: map_s2_015 | D20: STR_MAP_S2_015 | E20: STR_MAP_S2_015_DESC | F20: 2 | G20: 1 | H20: Talk | I20: 8.3 | J20: 7.3 | K20: 0 | L20: pf_Map_50018 | M20: img_map_0009 | N20: bgm_22 | O20: icon_map_0009 | P20: 1 | Q20: 0 | R20: drop_0009
A21: 50019 | B21: 무기 상인과 대화 | C21: map_s2_016 | D21: STR_MAP_S2_016 | E21: STR_MAP_S2_016_DESC | F21: 2 | G21: 1 | H21: Talk | I21: 8.3 | J21: 7.3 | K21: 0 | L21: pf_Map_50019 | M21: img_map_0009 | N21: bgm_22 | O21: icon_map_0009 | P21: 1 | Q21: 0 | R21: drop_0009
A22: 50020 | B22: 은둔 기사와 대화 | C22: map_s2_017 | D22: STR_MAP_S2_017 | E22: STR_MAP_S2_017_DESC | F22: 2 | G22: 1 | H22: Talk | I22: 8.3 | J22: 7.3 | K22: 0 | L22: pf_Map_50020 | M22: img_map_0009 | N22: bgm_22 | O22: icon_map_0009 | P22: 1 | Q22: 0 | R22: drop_0009
A23: 50021 | B23: 전직 기사와 대화 | C23: map_s2_018 | D23: STR_MAP_S2_018 | E23: STR_MAP_S2_018_DESC | F23: 2 | G23: 1 | H23: Talk | I23: 8.3 | J23: 7.3 | K23: 0 | L23: pf_Map_50021 | M23: img_map_0009 | N23: bgm_22 | O23: icon_map_0009 | P23: 1 | Q23: 0 | R23: drop_0009
A24: 50022 | B24: 전직 기사와 대화 | C24: map_s2_019 | D24: STR_MAP_S2_019 | E24: STR_MAP_S2_019_DESC | F24: 2 | G24: 1 | H24: Talk | I24: 8.3 | J24: 7.3 | K24: 0 | L24: pf_Map_50022 | M24: img_map_0009 | N24: bgm_22 | O24: icon_map_0009 | P24: 1 | Q24: 0 | R24: drop_0009
A25: 50023 | B25: 은둔 기사와 대화 | C25: map_s2_020 | D25: STR_MAP_S2_020 | E25: STR_MAP_S2_020_DESC | F25: 2 | G25: 1 | H25: Talk | I25: 8.3 | J25: 7.3 | K25: 0 | L25: pf_Map_50023 | M25: img_map_0009 | N25: bgm_22 | O25: icon_map_0009 | P25: 1 | Q25: 0 | R25: drop_0009
A26: 50024 | B26: 촌장님과 대화 | C26: map_s2_021 | D26: STR_MAP_S2_021 | E26: STR_MAP_S2_021_DESC | F26: 2 | G26: 1 | H26: SlowTalk | I26: 5 | J26: 4 | K26: 0 | L26: pf_Map_50024 | M26: img_map_0005 | N26: bgm_22 | O26: icon_map_0005 | P26: 1 | Q26: 0 | R26: drop_0009 | U26: drop_0010 | V26: drop_0011
A27: 50025 | B27: 마을 동쪽으로 | C27: map_s2_022 | D27: STR_MAP_S2_022 | E27: STR_MAP_S2_022_DESC | F27: 2 | G27: 1 | H27: Move | I27: 6.1 | J27: 5.1 | K27: 0 | L27: pf_Map_50025 | M27: img_map_0005 | N27: bgm_21 | O27: icon_map_0005 | P27: 1 | Q27: 0 | R27: drop_0009 | U27: drop_0010 | V27: drop_0011
A28: 50026 | B28: 경비병 엘런의 조언 | C28: map_s2_023 | D28: STR_MAP_S2_023 | E28: STR_MAP_S2_023_DESC | F28: 2 | G28: 1 | H28: Talk | I28: 5.1 | J28: 4.1 | K28: 0 | L28: pf_Map_50026 | M28: img_map_0010 | N28: bgm_22 | O28: icon_map_0010 | P28: 1 | Q28: 0 | R28: drop_0009
A29: 50027 | B29: 숨겨진 방으로 이동 | C29: map_s2_024 | D29: STR_MAP_S2_024 | E29: STR_MAP_S2_024_DESC | F29: 2 | G29: 1 | H29: Move | I29: 7.4 | J29: 6.4 | K29: 0 | L29: pf_Map_50027 | M29: img_map_0010 | N29: bgm_21 | O29: icon_map_0010 | P29: 1 | Q29: 0 | R29: drop_0009 | U29: drop_0010 | V29: drop_0011
A30: 50028 | B30: 숨겨진 방 | C30: map_s2_025 | D30: STR_MAP_S2_025 | E30: STR_MAP_S2_025_DESC | F30: 2 | G30: 1 | H30: Reward | I30: 1 | J30: 10 | K30: 0 | L30: pf_Map_50028 | M30: img_map_0011 | N30: bgm_02 | O30: icon_map_0011 | P30: 1 | Q30: 0 | R30: drop_0009
A31: 50029 | B31: 동쪽 숲으로 | C31: map_s2_026 | D31: STR_MAP_S2_026 | E31: STR_MAP_S2_026_DESC | F31: 2 | G31: 1 | H31: Move | I31: 8.2 | J31: 7.2 | K31: 0 | L31: pf_Map_50029 | M31: img_map_0010 | N31: bgm_21 | O31: icon_map_0010 | P31: 1 | Q31: 0 | R31: drop_0009 | U31: drop_0010 | V31: drop_0011
A32: 50030 | B32: 동쪽 숲 1 | C32: map_s3_001 | D32: STR_MAP_S3_001 | E32: STR_MAP_S3_001_DESC | F32: 3 | G32: 2 | H32: Move | I32: 3.5 | J32: 2.5 | K32: 0 | L32: pf_Map_50030 | M32: img_map_0012 | N32: bgm_31 | O32: icon_map_0012 | P32: 1 | Q32: 0 | R32: drop_0012 | U32: drop_0013 | V32: drop_0014
A33: 50031 | B33: 동쪽 숲 2 | C33: map_s3_002 | D33: STR_MAP_S3_002 | E33: STR_MAP_S3_002_DESC | F33: 3 | G33: 2 | H33: Move | I33: 4.1 | J33: 3.1 | K33: 0 | L33: pf_Map_50031 | M33: img_map_0013 | N33: bgm_34 | O33: icon_map_0013 | P33: 1 | Q33: 0 | R33: drop_0012 | U33: drop_0013 | V33: drop_0014
A34: 50032 | B34: 동쪽 숲 3 | C34: map_s3_003 | D34: STR_MAP_S3_003 | E34: STR_MAP_S3_003_DESC | F34: 3 | G34: 2 | H34: Move | I34: 7 | J34: 6 | K34: 0 | L34: pf_Map_50032 | M34: img_map_0014 | N34: bgm_34 | O34: icon_map_0014 | P34: 1 | Q34: 0 | R34: drop_0012 | U34: drop_0013 | V34: drop_0014
A35: 50033 | B35: 동쪽 숲 4 | C35: map_s3_004 | D35: STR_MAP_S3_004 | E35: STR_MAP_S3_004_DESC | F35: 3 | G35: 2 | H35: Move | I35: 2 | J35: 1 | K35: 0 | L35: pf_Map_50033 | M35: img_map_0015 | N35: bgm_31 | O35: icon_map_0015 | P35: 1 | Q35: 0 | R35: drop_0012 | U35: drop_0013 | V35: drop_0014
A36: 50034 | B36: 동쪽 숲 5 | C36: map_s3_005 | D36: STR_MAP_S3_005 | E36: STR_MAP_S3_005_DESC | F36: 3 | G36: 2 | H36: Move | I36: 5.8 | J36: 4.8 | K36: 0 | L36: pf_Map_50034 | M36: img_map_0016 | N36: bgm_34 | O36: icon_map_0016 | P36: 1 | Q36: 0 | R36: drop_0012 | U36: drop_0013 | V36: drop_0014
A37: 50035 | B37: 동쪽 숲 6 | C37: map_s3_006 | D37: STR_MAP_S3_006 | E37: STR_MAP_S3_006_DESC | F37: 3 | G37: 2 | H37: Move | I37: 4.7 | J37: 3.7 | K37: 0 | L37: pf_Map_50035 | M37: img_map_0018 | N37: bgm_34 | O37: icon_map_0018 | P37: 1 | Q37: 0 | R37: drop_0012 | U37: drop_0013 | V37: drop_0014
A38: 50036 | B38: 동쪽 숲 7 | C38: map_s3_007 | D38: STR_MAP_S3_007 | E38: STR_MAP_S3_007_DESC | F38: 3 | G38: 2 | H38: Move | I38: 5.8 | J38: 4.8 | K38: 0 | L38: pf_Map_50036 | M38: img_map_0019 | N38: bgm_34 | O38: icon_map_0019 | P38: 1 | Q38: 0 | R38: drop_0012 | U38: drop_0013 | V38: drop_0014
A39: 50037 | B39: 광산 마을 입구 | C39: map_s3_008 | D39: STR_MAP_S3_008 | E39: STR_MAP_S3_008_DESC | F39: 3 | G39: 2 | H39: Move | I39: 6.6 | J39: 5.6 | K39: 0 | L39: pf_Map_50037 | M39: img_map_0020 | N39: bgm_31 | O39: icon_map_0020 | P39: 1 | Q39: 0 | R39: drop_0012 | U39: drop_0013 | V39: drop_0014
A40: 50038 | B40: 죽은 자의 동굴 입구 | C40: map_s3_009 | D40: STR_MAP_S3_009 | E40: STR_MAP_S3_009_DESC | F40: 3 | G40: 2 | H40: Move | I40: 8.7 | J40: 7.7 | K40: 0 | L40: pf_Map_50038 | M40: img_map_0017 | N40: bgm_31 | O40: icon_map_0017 | P40: 1 | Q40: 0 | R40: drop_0012 | U40: drop_0013 | V40: drop_0014
...
