Workbook

Sheet History
A1: No | B1: 날짜 | C1: 작업자 | D1: 문서 변경 내용
A2: 1 | B2: 42479 | C2: 변동언 | D2: [file] 최초 작성

Sheet 계약서
A3: 수익 분배 계약서
B6: 각 작업자는 스마트폰 게임 짱 : 서울일통(가칭, 이하 게임)의 수익에 대해 위 수익 분배 비율에 따라 수익을 나눔에 동의합니다.
B7: 수익이란 제반비용을 제외한 순수익을 말합니다.
B8: 제반비용이란 마켓 수수료, 외주비용, 기타 게임 개발에 사용된 비용을 말합니다.
B9: 작업물에 대한 모든 권리는 각 작업자가 가집니다. 본 게임 이외에서 작업물을 사용하기 위해서는 권리자에게 사용 허락을 얻어야 합니다.
B10: 본 계약은 각 작업자가 회신하며, 동의란에 본인의 성명을 기재하여 SVN에 업데이트 하는 것으로 서명,날인을 대신합니다.
B12: ▶ 수익 분배 비율
B13: 작업자 | C13: =IF(Sheet3!L$1=0,"",Sheet3!L$1) -> 변동언 | D13: =IF(Sheet3!M$1=0,"",Sheet3!M$1) -> 김경훈 | E13: =IF(Sheet3!N$1=0,"",Sheet3!N$1) -> 박종혁 | F13: =IF(Sheet3!O$1=0,"",Sheet3!O$1) | G13: =IF(Sheet3!P$1=0,"",Sheet3!P$1) | H13: =IF(Sheet3!Q$1=0,"",Sheet3!Q$1) | I13: =IF(Sheet3!R$1=0,"",Sheet3!R$1) | J13: =IF(Sheet3!S$1=0,"",Sheet3!S$1) | ... M13: =IF(Sheet3!V$1=0,"",Sheet3!V$1) | N13: 합계
B14: 지분비율 | C14: =SUM(Sheet3!A:A) -> 0.85135662 | D14: =SUM(Sheet3!B:B) -> 0.049586777 | E14: =SUM(Sheet3!C:C) -> 0.099056604 | N14: =SUM(C14:M14) -> 1
B15: 동의

Sheet 업무할당
A1: 분류 | D1: 업무 | E1: 할당 | H1: 적용비율 | I1: 담당자
A2: 관리 | B2: 전체 | E2: 0.02 | F2: 0.02 | G2: =SUM(G3:G4) -> 1 | H2: =SUM(H3:H4) -> 0.02
B3: 디렉팅 | F3: 0.02 | G3: 0.5 | H3: =F3*G3/G$2 -> 0.01 | I3: 변동언
B4: 프로젝트 관리 | F4: 0.02 | G4: 0.5 | H4: =F4*G4/G$2 -> 0.01 | I4: 변동언
A5: 프로그램 | B5: 전체 | E5: 0.25 | F5: 0.25 | G5: =SUM(G6:G10) -> 1 | H5: =SUM(H6:H10) -> 0.25
B6: 게임 구현 | C6: 게임 클라이언트 코드 구현 | F6: 0.25 | G6: 0.9 | H6: =F6*G6/G$5 -> 0.225 | I6: 변동언
C7: 맵 배치 툴 제작 | F7: 0.25 | G7: 0.05 | H7: =F7*G7/G$5 -> 0.0125 | I7: 변동언
C8: 소셜 기능 구현 | F8: 0.25 | G8: 0.05 | H8: =F8*G8/G$5 -> 0.0125 | I8: 변동언
F9: 0.25 | G9: 0 | H9: =F9*G9/G$5 -> 0
F10: 0.25 | G10: 0 | H10: =F10*G10/G$5 -> 0
A11: 기획 | B11: 전체 | E11: 0.2 | F11: 0.2 | G11: =SUM(G12:G50) -> 1.21 | H11: =SUM(H12:H50) -> 0.2
B12: 시스템 | C12: 타이틀 시스템 | F12: 0.2 | G12: 0.01 | H12: =F12*G12/G$11 -> 0.0016528926 | I12: 변동언
C13: 메뉴 시스템 | F13: 0.2 | G13: 0.01 | H13: =F13*G13/G$11 -> 0.0016528926 | I13: 변동언
C14: 세이브 시스템 | F14: 0.2 | G14: 0.01 | H14: =F14*G14/G$11 -> 0.0016528926 | I14: 변동언
C15: 생성 시스템 | F15: 0.2 | G15: 0.01 | H15: =F15*G15/G$11 -> 0.0016528926 | I15: 변동언
C16: 지역 시스템 | F16: 0.2 | G16: 0.01 | H16: =F16*G16/G$11 -> 0.0016528926 | I16: 변동언
C17: 세력 시스팀 | F17: 0.2 | G17: 0.01 | H17: =F17*G17/G$11 -> 0.0016528926 | I17: 변동언
C18: 멤버 시스템 | F18: 0.2 | G18: 0.01 | H18: =F18*G18/G$11 -> 0.0016528926 | I18: 변동언
C19: 명령 시스템 | F19: 0.2 | G19: 0.05 | H19: =F19*G19/G$11 -> 0.0082644628 | I19: 변동언
C20: AI 시스템 | F20: 0.2 | G20: 0.1 | H20: =F20*G20/G$11 -> 0.016528926 | I20: 변동언
C21: 게임 시스템 | F21: 0.2 | G21: 0.1 | H21: =F21*G21/G$11 -> 0.016528926 | I21: 변동언
C22: 엔딩 크레딧 시스템 | F22: 0.2 | G22: 0.01 | H22: =F22*G22/G$11 -> 0.0016528926 | I22: 변동언
C23: 사운드 시스템 | F23: 0.2 | G23: 0.01 | H23: =F23*G23/G$11 -> 0.0016528926 | I23: 변동언
C24: 게임 설정 시스템 | F24: 0.2 | G24: 0.01 | H24: =F24*G24/G$11 -> 0.0016528926 | I24: 변동언
... C29: 멤버 설정 툴 | F29: 0.2 | G29: 0.02 | H29: =F29*G29/G$11 -> 0.0033057851 | I29: 변동언
F30: 0.2 | G30: 0 | H30: =F30*G30/G$11 -> 0
B31: 컨텐츠 | C31: 시나리오, 게임 컨셉 | F31: 0.2 | G31: 0.3 | H31: =F31*G31/G$11 -> 0.049586777 | I31: 김경훈
C32: 타이틀 씬 설정 | F32: 0.2 | G32: 0.01 | H32: =F32*G32/G$11 -> 0.0016528926 | I32: 변동언
C33: 메뉴 씬 설정 | F33: 0.2 | G33: 0.01 | H33: =F33*G33/G$11 -> 0.0016528926 | I33: 변동언
C34: 생성 씬 설정 | F34: 0.2 | G34: 0.01 | H34: =F34*G34/G$11 -> 0.0016528926 | I34: 변동언
C35: 로딩 씬 설정 | F35: 0.2 | G35: 0.01 | H35: =F35*G35/G$11 -> 0.0016528926 | I35: 변동언
C36: 게임 씬 설정 | F36: 0.2 | G36: 0.01 | H36: =F36*G36/G$11 -> 0.0016528926 | I36: 변동언
C37: 엔딩 씬 설정 | F37: 0.2 | G37: 0.01 | H37: =F37*G37/G$11 -> 0.0016528926 | I37: 변동언
C38: 크레딧 씬 설정 | F38: 0.2 | G38: 0.01 | H38: =F38*G38/G$11 -> 0.0016528926 | I38: 변동언
C39: 지역 설정 및 데이터 작업 | F39: 0.2 | G39: 0.01 | H39: =F39*G39/G$11 -> 0.0016528926 | I39: 변동언
C40: 세력 설정 및 데이터 작업 | F40: 0.2 | G40: 0.05 | H40: =F40*G40/G$11 -> 0.0082644628 | I40: 변동언
C41: 멤버 설정 및 데이터 작업 | F41: 0.2 | G41: 0.1 | H41: =F41*G41/G$11 -> 0.016528926 | I41: 변동언
C42: 옵션 설정 및 데이터 작업 | F42: 0.2 | G42: 0.01 | H42: =F42*G42/G$11 -> 0.0016528926 | I42: 변동언
C43: 사운드 설정 및 데이터 작업 | F43: 0.2 | G43: 0.01 | H43: =F43*G43/G$11 -> 0.0016528926 | I43: 변동언
... C46: 맵 구성 및 배치 | F46: 0.2 | G46: 0.05 | H46: =F46*G46/G$11 -> 0.0082644628 | I46: 변동언
...

Sheet Sheet3
A1: =IF(L$1=업무할당!$I2,업무할당!$H2,0) -> 0 | B1: =IF(M$1=업무할당!$I2,업무할당!$H2,0) -> 0 | C1: =IF(N$1=업무할당!$I2,업무할당!$H2,0) -> 0 | L1: 변동언 | M1: 김경훈 | N1: 박종혁
A2: =IF(L$1=업무할당!$I3,업무할당!$H3,0) -> 0.01 | B2: =IF(M$1=업무할당!$I3,업무할당!$H3,0) -> 0 | C2: =IF(N$1=업무할당!$I3,업무할당!$H3,0) -> 0
A3: =IF(L$1=업무할당!$I4,업무할당!$H4,0) -> 0.01 | B3: =IF(M$1=업무할당!$I4,업무할당!$H4,0) -> 0 | C3: =IF(N$1=업무할당!$I4,업무할당!$H4,0) -> 0
A4: =IF(L$1=업무할당!$I5,업무할당!$H5,0) -> 0 | B4: =IF(M$1=업무할당!$I5,업무할당!$H5,0) -> 0 | C4: =IF(N$1=업무할당!$I5,업무할당!$H5,0) -> 0
A5: =IF(L$1=업무할당!$I6,업무할당!$H6,0) -> 0.225 | B5: =IF(M$1=업무할당!$I6,업무할당!$H6,0) -> 0 | C5: =IF(N$1=업무할당!$I6,업무할당!$H6,0) -> 0
A6: =IF(L$1=업무할당!$I7,업무할당!$H7,0) -> 0.0125 | B6: =IF(M$1=업무할당!$I7,업무할당!$H7,0) -> 0 | C6: =IF(N$1=업무할당!$I7,업무할당!$H7,0) -> 0
A7: =IF(L$1=업무할당!$I8,업무할당!$H8,0) -> 0.0125 | B7: =IF(M$1=업무할당!$I8,업무할당!$H8,0) -> 0 | C7: =IF(N$1=업무할당!$I8,업무할당!$H8,0) -> 0
A8: =IF(L$1=업무할당!$I9,업무할당!$H9,0) -> 0 | B8: =IF(M$1=업무할당!$I9,업무할당!$H9,0) -> 0 | C8: =IF(N$1=업무할당!$I9,업무할당!$H9,0) -> 0
A9: =IF(L$1=업무할당!$I10,업무할당!$H10,0) -> 0 | B9: =IF(M$1=업무할당!$I10,업무할당!$H10,0) -> 0 | C9: =IF(N$1=업무할당!$I10,업무할당!$H10,0) -> 0
A10: =IF(L$1=업무할당!$I11,업무할당!$H11,0) -> 0 | B10: =IF(M$1=업무할당!$I11,업무할당!$H11,0) -> 0 | C10: =IF(N$1=업무할당!$I11,업무할당!$H11,0) -> 0
A11: =IF(L$1=업무할당!$I12,업무할당!$H12,0) -> 0.0016528926 | B11: =IF(M$1=업무할당!$I12,업무할당!$H12,0) -> 0 | C11: =IF(N$1=업무할당!$I12,업무할당!$H12,0) -> 0
A12: =IF(L$1=업무할당!$I13,업무할당!$H13,0) -> 0.0016528926 | B12: =IF(M$1=업무할당!$I13,업무할당!$H13,0) -> 0 | C12: =IF(N$1=업무할당!$I13,업무할당!$H13,0) -> 0
A13: =IF(L$1=업무할당!$I14,업무할당!$H14,0) -> 0.0016528926 | B13: =IF(M$1=업무할당!$I14,업무할당!$H14,0) -> 0 | C13: =IF(N$1=업무할당!$I14,업무할당!$H14,0) -> 0
... A205: =IF(L$1=업무할당!$I206,업무할당!$H206,0) -> 0 | B205: =IF(M$1=업무할당!$I206,업무할당!$H206,0) -> 0 | C205: =IF(N$1=업무할당!$I206,업무할당!$H206,0) -> 0

Sheet 비용정산
A1: 항목 | B1: 내용 | C1: 비용 | D1: 부담자 | E1: 정산일 | F1: 비고 | H1: 정산일 | I1: 합계
A2: 광고 | B2: 페이스북 광고 | C2: 35000 | D2: 변동언 | H2: 2016.05.20 | I2: =SUMIF(E:E,H2,C:C) -> 0
A3: 광고 | B3: 페이스북 광고 | C3: 85000 | D3: 변동언 | I3: =SUMIF(E:E,H3,C:C) -> 0
A4: 광고 | B4: 페이스북 광고 | C4: 35000 | D4: 변동언 | I4: =SUMIF(E:E,H4,C:C) -> 0
A5: 광고 | B5: 구글 광고 | C5: 200000 | D5: 변동언 | I5: =SUMIF(E:E,H5,C:C) -> 0
I6: =SUMIF(E:E,H6,C:C) -> 0
I7: =SUMIF(E:E,H7,C:C) -> 0
I8: =SUMIF(E:E,H8,C:C) -> 0
I9: =SUMIF(E:E,H9,C:C) -> 0
I10: =SUMIF(E:E,H10,C:C) -> 0
I11: =SUMIF(E:E,H11,C:C) -> 0
I12: =SUMIF(E:E,H12,C:C) -> 0
I13: =SUMIF(E:E,H13,C:C) -> 0
I14: =SUMIF(E:E,H14,C:C) -> 0
I15: =SUMIF(E:E,H15,C:C) -> 0
I16: =SUMIF(E:E,H16,C:C) -> 0
I17: =SUMIF(E:E,H17,C:C) -> 0
... I22: =SUMIF(E:E,H22,C:C) -> 0

Sheet 수익정산
A1: 구분 | B1: 지급일 | C1: 정산일 | D1: 판매기간 | G1: 수익 | H1: 비용 | I1: 순수익 | J1: 김경훈 | K1: 변동언 | L1: 박종혁 | M1: 비고
A2: 구글 | B2: 2016.05.20 | E2: ~ | G2: 0 | H2: =VLOOKUP(C2,비용정산!H:I,2,FALSE) -> #N/A | I2: =G2-H2 -> #N/A | J2: =ROUND(HLOOKUP(J$1,계약서!$C$13:$M$14,2,FALSE)*$I2,0) -> #N/A | K2: =ROUND(HLOOKUP(K$1,계약서!$C$13:$M$14,2,FALSE)*$I2,0) -> #N/A | L2: =ROUND(HLOOKUP(L$1,계약서!$C$13:$M$14,2,FALSE)*$I2,0) -> #N/A
